{
  "cells": [
    {
      "cell_type": "code",
      "execution_count": null,
      "metadata": {
        "colab": {
          "base_uri": "https://localhost:8080/"
        },
        "id": "hT9kZNaX33Qr",
        "outputId": "e94b5792-3a90-4b75-f99b-e0ea8e59fba0"
      },
      "outputs": [
        {
          "name": "stdout",
          "output_type": "stream",
          "text": [
            "\u001b[2K     \u001b[90m━━━━━━━━━━━━━━━━━━━━━━━━━━━━━━━━━━━━━━━━\u001b[0m \u001b[32m8.6/8.6 MB\u001b[0m \u001b[31m13.0 MB/s\u001b[0m eta \u001b[36m0:00:00\u001b[0m\n",
            "\u001b[2K     \u001b[90m━━━━━━━━━━━━━━━━━━━━━━━━━━━━━━━━━━━━━━━━\u001b[0m \u001b[32m207.3/207.3 kB\u001b[0m \u001b[31m13.1 MB/s\u001b[0m eta \u001b[36m0:00:00\u001b[0m\n",
            "\u001b[2K     \u001b[90m━━━━━━━━━━━━━━━━━━━━━━━━━━━━━━━━━━━━━━━━\u001b[0m \u001b[32m6.9/6.9 MB\u001b[0m \u001b[31m44.7 MB/s\u001b[0m eta \u001b[36m0:00:00\u001b[0m\n",
            "\u001b[2K     \u001b[90m━━━━━━━━━━━━━━━━━━━━━━━━━━━━━━━━━━━━━━━━\u001b[0m \u001b[32m83.0/83.0 kB\u001b[0m \u001b[31m2.5 MB/s\u001b[0m eta \u001b[36m0:00:00\u001b[0m\n",
            "\u001b[2K     \u001b[90m━━━━━━━━━━━━━━━━━━━━━━━━━━━━━━━━━━━━━━━━\u001b[0m \u001b[32m62.7/62.7 kB\u001b[0m \u001b[31m5.2 MB/s\u001b[0m eta \u001b[36m0:00:00\u001b[0m\n",
            "\u001b[?25h"
          ]
        }
      ],
      "source": [
        "!pip install streamlit -q"
      ]
    },
    {
      "cell_type": "code",
      "execution_count": null,
      "metadata": {
        "colab": {
          "base_uri": "https://localhost:8080/"
        },
        "id": "B95XN3Zl94Ph",
        "outputId": "f38e2c8d-7c90-4c0c-b93e-5c858cc8702d"
      },
      "outputs": [
        {
          "name": "stdout",
          "output_type": "stream",
          "text": [
            "34.70.124.163\n"
          ]
        }
      ],
      "source": [
        "!wget -q -O - ipv4.icanhazip.com"
      ]
    },
    {
      "cell_type": "code",
      "execution_count": null,
      "metadata": {
        "colab": {
          "base_uri": "https://localhost:8080/"
        },
        "id": "eWvg_kqZ9_Pt",
        "outputId": "5d077428-01b5-4b5e-98b0-2af9cf3e403e"
      },
      "outputs": [
        {
          "name": "stdout",
          "output_type": "stream",
          "text": [
            "Writing web.py\n"
          ]
        }
      ],
      "source": [
        "%%writefile web.py"
      ]
    },
    {
      "cell_type": "code",
      "execution_count": null,
      "metadata": {
        "colab": {
          "base_uri": "https://localhost:8080/"
        },
        "id": "1J1eIqgS-GJa",
        "outputId": "b8e8f9f8-ec0e-4181-87f2-e72a014aa276"
      },
      "outputs": [
        {
          "name": "stdout",
          "output_type": "stream",
          "text": [
            "\u001b[K\u001b[?25h\u001b[37;40mnpm\u001b[0m \u001b[0m\u001b[30;43mWARN\u001b[0m \u001b[0m\u001b[35msaveError\u001b[0m ENOENT: no such file or directory, open '/content/package.json'\n",
            "\u001b[0m\u001b[37;40mnpm\u001b[0m \u001b[0m\u001b[34;40mnotice\u001b[0m\u001b[35m\u001b[0m created a lockfile as package-lock.json. You should commit this file.\n",
            "\u001b[K\u001b[?25h\u001b[37;40mnpm\u001b[0m \u001b[0m\u001b[30;43mWARN\u001b[0m \u001b[0m\u001b[35menoent\u001b[0m ENOENT: no such file or directory, open '/content/package.json'\n",
            "\u001b[0m\u001b[37;40mnpm\u001b[0m \u001b[0m\u001b[30;43mWARN\u001b[0m\u001b[35m\u001b[0m content No description\n",
            "\u001b[0m\u001b[37;40mnpm\u001b[0m \u001b[0m\u001b[30;43mWARN\u001b[0m\u001b[35m\u001b[0m content No repository field.\n",
            "\u001b[0m\u001b[37;40mnpm\u001b[0m \u001b[0m\u001b[30;43mWARN\u001b[0m\u001b[35m\u001b[0m content No README data\n",
            "\u001b[0m\u001b[37;40mnpm\u001b[0m \u001b[0m\u001b[30;43mWARN\u001b[0m\u001b[35m\u001b[0m content No license field.\n",
            "\u001b[0m\n",
            "+ localtunnel@2.0.2\n",
            "added 22 packages from 22 contributors and audited 22 packages in 2.427s\n",
            "\n",
            "3 packages are looking for funding\n",
            "  run `npm fund` for details\n",
            "\n",
            "found 1 \u001b[93mmoderate\u001b[0m severity vulnerability\n",
            "  run `npm audit fix` to fix them, or `npm audit` for details\n",
            "\u001b[K\u001b[?25h"
          ]
        }
      ],
      "source": [
        "!npm install localtunnel"
      ]
    },
    {
      "cell_type": "code",
      "execution_count": 5,
      "metadata": {
        "colab": {
          "base_uri": "https://localhost:8080/"
        },
        "id": "jGTPduWp-NDX",
        "outputId": "c27fc0a6-65e8-40af-ed39-a7c6062f3ad8"
      },
      "outputs": [
        {
          "output_type": "stream",
          "name": "stdout",
          "text": [
            "[..................] \\ fetchMetadata: sill resolveWithNewModule localtunnel@2.0\u001b[0m\u001b[K\n",
            "Collecting usage statistics. To deactivate, set browser.gatherUsageStats to false.\n",
            "\u001b[0m\n",
            "\u001b[0m\n",
            "\u001b[34m\u001b[1m  You can now view your Streamlit app in your browser.\u001b[0m\n",
            "\u001b[0m\n",
            "\u001b[34m  Local URL: \u001b[0m\u001b[1mhttp://localhost:8501\u001b[0m\n",
            "\u001b[34m  Network URL: \u001b[0m\u001b[1mhttp://172.28.0.12:8501\u001b[0m\n",
            "\u001b[34m  External URL: \u001b[0m\u001b[1mhttp://34.70.124.163:8501\u001b[0m\n",
            "\u001b[0m\n",
            "\u001b[K\u001b[?25hnpx: installed 22 in 2.165s\n",
            "your url is: https://witty-doodles-fetch.loca.lt\n",
            "2024-07-02 15:13:26.416 Uncaught app exception\n",
            "Traceback (most recent call last):\n",
            "  File \"/usr/local/lib/python3.10/dist-packages/streamlit/runtime/scriptrunner/script_runner.py\", line 589, in _run_script\n",
            "    exec(code, module.__dict__)\n",
            "  File \"/content/web.py\", line 5, in <module>\n",
            "    model=joblib.load('KNN.joblib')\n",
            "  File \"/usr/local/lib/python3.10/dist-packages/joblib/numpy_pickle.py\", line 650, in load\n",
            "    with open(filename, 'rb') as f:\n",
            "FileNotFoundError: [Errno 2] No such file or directory: 'KNN.joblib'\n",
            "2024-07-02 15:21:42.925 Uncaught app exception\n",
            "Traceback (most recent call last):\n",
            "  File \"/usr/local/lib/python3.10/dist-packages/streamlit/runtime/scriptrunner/script_runner.py\", line 589, in _run_script\n",
            "    exec(code, module.__dict__)\n",
            "  File \"/content/web.py\", line 9, in <module>\n",
            "    df[col]=a.fit_transform(df[col])\n",
            "NameError: name 'df' is not defined\n",
            "2024-07-02 15:22:13.130 Uncaught app exception\n",
            "Traceback (most recent call last):\n",
            "  File \"/usr/local/lib/python3.10/dist-packages/streamlit/runtime/scriptrunner/script_runner.py\", line 589, in _run_script\n",
            "    exec(code, module.__dict__)\n",
            "  File \"/content/web.py\", line 9, in <module>\n",
            "    df[col]=a.fit_transform(df[col])\n",
            "NameError: name 'df' is not defined\n",
            "2024-07-02 15:22:42.965 Uncaught app exception\n",
            "Traceback (most recent call last):\n",
            "  File \"/usr/local/lib/python3.10/dist-packages/streamlit/runtime/scriptrunner/script_runner.py\", line 589, in _run_script\n",
            "    exec(code, module.__dict__)\n",
            "  File \"/content/web.py\", line 11, in <module>\n",
            "    df[col]=a.fit_transform(df[col])\n",
            "NameError: name 'df' is not defined\n",
            "2024-07-02 15:22:42.974 Uncaught app exception\n",
            "Traceback (most recent call last):\n",
            "  File \"/usr/local/lib/python3.10/dist-packages/streamlit/runtime/scriptrunner/script_runner.py\", line 589, in _run_script\n",
            "    exec(code, module.__dict__)\n",
            "  File \"/content/web.py\", line 11, in <module>\n",
            "    df[col]=a.fit_transform(df[col])\n",
            "NameError: name 'df' is not defined\n",
            "2024-07-02 15:31:12.785 Uncaught app exception\n",
            "Traceback (most recent call last):\n",
            "  File \"/usr/local/lib/python3.10/dist-packages/streamlit/runtime/scriptrunner/script_runner.py\", line 589, in _run_script\n",
            "    exec(code, module.__dict__)\n",
            "  File \"/content/web.py\", line 59, in <module>\n",
            "    main()\n",
            "  File \"/content/web.py\", line 56, in main\n",
            "    st.success(diagnosis)\n",
            "NameError: name 'diagnosis' is not defined\n",
            "2024-07-02 15:33:13.013 Uncaught app exception\n",
            "Traceback (most recent call last):\n",
            "  File \"/usr/local/lib/python3.10/dist-packages/streamlit/runtime/scriptrunner/script_runner.py\", line 589, in _run_script\n",
            "    exec(code, module.__dict__)\n",
            "  File \"/content/web.py\", line 59, in <module>\n",
            "    main()\n",
            "  File \"/content/web.py\", line 35, in main\n",
            "    Sex=st.selec('Sex')\n",
            "AttributeError: module 'streamlit' has no attribute 'selec'\n",
            "2024-07-02 15:33:35.679 Uncaught app exception\n",
            "Traceback (most recent call last):\n",
            "  File \"/usr/local/lib/python3.10/dist-packages/streamlit/runtime/scriptrunner/script_runner.py\", line 589, in _run_script\n",
            "    exec(code, module.__dict__)\n",
            "  File \"/content/web.py\", line 59, in <module>\n",
            "    main()\n",
            "  File \"/content/web.py\", line 35, in main\n",
            "    Sex=st.select('choose',['Male','Female'])\n",
            "AttributeError: module 'streamlit' has no attribute 'select'\n",
            "/usr/local/lib/python3.10/dist-packages/sklearn/base.py:439: UserWarning: X does not have valid feature names, but RandomForestClassifier was fitted with feature names\n",
            "  warnings.warn(\n",
            "2024-07-02 15:36:51.435 Uncaught app exception\n",
            "Traceback (most recent call last):\n",
            "  File \"/usr/local/lib/python3.10/dist-packages/streamlit/runtime/scriptrunner/script_runner.py\", line 589, in _run_script\n",
            "    exec(code, module.__dict__)\n",
            "  File \"/content/web.py\", line 59, in <module>\n",
            "    main()\n",
            "  File \"/content/web.py\", line 54, in main\n",
            "    survive=survival_prediction([Age,SibSp,Pclass,Parch,PassengerId,Sex,Fare,Embarked])\n",
            "  File \"/content/web.py\", line 20, in survival_prediction\n",
            "    prediction=model.predict(b)\n",
            "  File \"/usr/local/lib/python3.10/dist-packages/sklearn/ensemble/_forest.py\", line 820, in predict\n",
            "    proba = self.predict_proba(X)\n",
            "  File \"/usr/local/lib/python3.10/dist-packages/sklearn/ensemble/_forest.py\", line 862, in predict_proba\n",
            "    X = self._validate_X_predict(X)\n",
            "  File \"/usr/local/lib/python3.10/dist-packages/sklearn/ensemble/_forest.py\", line 602, in _validate_X_predict\n",
            "    X = self._validate_data(X, dtype=DTYPE, accept_sparse=\"csr\", reset=False)\n",
            "  File \"/usr/local/lib/python3.10/dist-packages/sklearn/base.py\", line 565, in _validate_data\n",
            "    X = check_array(X, input_name=\"X\", **check_params)\n",
            "  File \"/usr/local/lib/python3.10/dist-packages/sklearn/utils/validation.py\", line 879, in check_array\n",
            "    array = _asarray_with_order(array, order=order, dtype=dtype, xp=xp)\n",
            "  File \"/usr/local/lib/python3.10/dist-packages/sklearn/utils/_array_api.py\", line 185, in _asarray_with_order\n",
            "    array = numpy.asarray(array, order=order, dtype=dtype)\n",
            "ValueError: could not convert string to float: 'Male'\n",
            "/usr/local/lib/python3.10/dist-packages/sklearn/base.py:439: UserWarning: X does not have valid feature names, but RandomForestClassifier was fitted with feature names\n",
            "  warnings.warn(\n",
            "2024-07-02 15:37:57.081 Uncaught app exception\n",
            "Traceback (most recent call last):\n",
            "  File \"/usr/local/lib/python3.10/dist-packages/streamlit/runtime/scriptrunner/script_runner.py\", line 589, in _run_script\n",
            "    exec(code, module.__dict__)\n",
            "  File \"/content/web.py\", line 60, in <module>\n",
            "    main()\n",
            "  File \"/content/web.py\", line 55, in main\n",
            "    survive=survival_prediction([Age,SibSp,Pclass,Parch,PassengerId,Sex,Fare,Embarked])\n",
            "  File \"/content/web.py\", line 20, in survival_prediction\n",
            "    prediction=model.predict(b)\n",
            "  File \"/usr/local/lib/python3.10/dist-packages/sklearn/ensemble/_forest.py\", line 820, in predict\n",
            "    proba = self.predict_proba(X)\n",
            "  File \"/usr/local/lib/python3.10/dist-packages/sklearn/ensemble/_forest.py\", line 862, in predict_proba\n",
            "    X = self._validate_X_predict(X)\n",
            "  File \"/usr/local/lib/python3.10/dist-packages/sklearn/ensemble/_forest.py\", line 602, in _validate_X_predict\n",
            "    X = self._validate_data(X, dtype=DTYPE, accept_sparse=\"csr\", reset=False)\n",
            "  File \"/usr/local/lib/python3.10/dist-packages/sklearn/base.py\", line 565, in _validate_data\n",
            "    X = check_array(X, input_name=\"X\", **check_params)\n",
            "  File \"/usr/local/lib/python3.10/dist-packages/sklearn/utils/validation.py\", line 879, in check_array\n",
            "    array = _asarray_with_order(array, order=order, dtype=dtype, xp=xp)\n",
            "  File \"/usr/local/lib/python3.10/dist-packages/sklearn/utils/_array_api.py\", line 185, in _asarray_with_order\n",
            "    array = numpy.asarray(array, order=order, dtype=dtype)\n",
            "ValueError: could not convert string to float: 'Male'\n",
            "/usr/local/lib/python3.10/dist-packages/sklearn/base.py:439: UserWarning: X does not have valid feature names, but RandomForestClassifier was fitted with feature names\n",
            "  warnings.warn(\n",
            "2024-07-02 15:37:59.928 Uncaught app exception\n",
            "Traceback (most recent call last):\n",
            "  File \"/usr/local/lib/python3.10/dist-packages/streamlit/runtime/scriptrunner/script_runner.py\", line 589, in _run_script\n",
            "    exec(code, module.__dict__)\n",
            "  File \"/content/web.py\", line 60, in <module>\n",
            "    main()\n",
            "  File \"/content/web.py\", line 55, in main\n",
            "    survive=survival_prediction([Age,SibSp,Pclass,Parch,PassengerId,Sex,Fare,Embarked])\n",
            "  File \"/content/web.py\", line 20, in survival_prediction\n",
            "    prediction=model.predict(b)\n",
            "  File \"/usr/local/lib/python3.10/dist-packages/sklearn/ensemble/_forest.py\", line 820, in predict\n",
            "    proba = self.predict_proba(X)\n",
            "  File \"/usr/local/lib/python3.10/dist-packages/sklearn/ensemble/_forest.py\", line 862, in predict_proba\n",
            "    X = self._validate_X_predict(X)\n",
            "  File \"/usr/local/lib/python3.10/dist-packages/sklearn/ensemble/_forest.py\", line 602, in _validate_X_predict\n",
            "    X = self._validate_data(X, dtype=DTYPE, accept_sparse=\"csr\", reset=False)\n",
            "  File \"/usr/local/lib/python3.10/dist-packages/sklearn/base.py\", line 565, in _validate_data\n",
            "    X = check_array(X, input_name=\"X\", **check_params)\n",
            "  File \"/usr/local/lib/python3.10/dist-packages/sklearn/utils/validation.py\", line 879, in check_array\n",
            "    array = _asarray_with_order(array, order=order, dtype=dtype, xp=xp)\n",
            "  File \"/usr/local/lib/python3.10/dist-packages/sklearn/utils/_array_api.py\", line 185, in _asarray_with_order\n",
            "    array = numpy.asarray(array, order=order, dtype=dtype)\n",
            "ValueError: could not convert string to float: 'Male'\n",
            "/usr/local/lib/python3.10/dist-packages/sklearn/base.py:439: UserWarning: X does not have valid feature names, but RandomForestClassifier was fitted with feature names\n",
            "  warnings.warn(\n",
            "2024-07-02 15:39:02.812 Uncaught app exception\n",
            "Traceback (most recent call last):\n",
            "  File \"/usr/local/lib/python3.10/dist-packages/streamlit/runtime/scriptrunner/script_runner.py\", line 589, in _run_script\n",
            "    exec(code, module.__dict__)\n",
            "  File \"/content/web.py\", line 60, in <module>\n",
            "    main()\n",
            "  File \"/content/web.py\", line 55, in main\n",
            "    survive=survival_prediction([Age,SibSp,Pclass,Parch,PassengerId,Sex,Fare,Embarked])\n",
            "  File \"/content/web.py\", line 20, in survival_prediction\n",
            "    prediction=model.predict(b)\n",
            "  File \"/usr/local/lib/python3.10/dist-packages/sklearn/ensemble/_forest.py\", line 820, in predict\n",
            "    proba = self.predict_proba(X)\n",
            "  File \"/usr/local/lib/python3.10/dist-packages/sklearn/ensemble/_forest.py\", line 862, in predict_proba\n",
            "    X = self._validate_X_predict(X)\n",
            "  File \"/usr/local/lib/python3.10/dist-packages/sklearn/ensemble/_forest.py\", line 602, in _validate_X_predict\n",
            "    X = self._validate_data(X, dtype=DTYPE, accept_sparse=\"csr\", reset=False)\n",
            "  File \"/usr/local/lib/python3.10/dist-packages/sklearn/base.py\", line 565, in _validate_data\n",
            "    X = check_array(X, input_name=\"X\", **check_params)\n",
            "  File \"/usr/local/lib/python3.10/dist-packages/sklearn/utils/validation.py\", line 879, in check_array\n",
            "    array = _asarray_with_order(array, order=order, dtype=dtype, xp=xp)\n",
            "  File \"/usr/local/lib/python3.10/dist-packages/sklearn/utils/_array_api.py\", line 185, in _asarray_with_order\n",
            "    array = numpy.asarray(array, order=order, dtype=dtype)\n",
            "ValueError: could not convert string to float: ''\n",
            "/usr/local/lib/python3.10/dist-packages/sklearn/base.py:439: UserWarning: X does not have valid feature names, but RandomForestClassifier was fitted with feature names\n",
            "  warnings.warn(\n",
            "2024-07-02 15:40:40.608 Uncaught app exception\n",
            "Traceback (most recent call last):\n",
            "  File \"/usr/local/lib/python3.10/dist-packages/streamlit/runtime/scriptrunner/script_runner.py\", line 589, in _run_script\n",
            "    exec(code, module.__dict__)\n",
            "  File \"/content/web.py\", line 61, in <module>\n",
            "    main()\n",
            "  File \"/content/web.py\", line 56, in main\n",
            "    survive=survival_prediction([Age,SibSp,Pclass,Parch,PassengerId,Sex,Fare,Embarked])\n",
            "  File \"/content/web.py\", line 20, in survival_prediction\n",
            "    prediction=model.predict(b)\n",
            "  File \"/usr/local/lib/python3.10/dist-packages/sklearn/ensemble/_forest.py\", line 820, in predict\n",
            "    proba = self.predict_proba(X)\n",
            "  File \"/usr/local/lib/python3.10/dist-packages/sklearn/ensemble/_forest.py\", line 862, in predict_proba\n",
            "    X = self._validate_X_predict(X)\n",
            "  File \"/usr/local/lib/python3.10/dist-packages/sklearn/ensemble/_forest.py\", line 602, in _validate_X_predict\n",
            "    X = self._validate_data(X, dtype=DTYPE, accept_sparse=\"csr\", reset=False)\n",
            "  File \"/usr/local/lib/python3.10/dist-packages/sklearn/base.py\", line 565, in _validate_data\n",
            "    X = check_array(X, input_name=\"X\", **check_params)\n",
            "  File \"/usr/local/lib/python3.10/dist-packages/sklearn/utils/validation.py\", line 879, in check_array\n",
            "    array = _asarray_with_order(array, order=order, dtype=dtype, xp=xp)\n",
            "  File \"/usr/local/lib/python3.10/dist-packages/sklearn/utils/_array_api.py\", line 185, in _asarray_with_order\n",
            "    array = numpy.asarray(array, order=order, dtype=dtype)\n",
            "ValueError: could not convert string to float: 'Male'\n",
            "/usr/local/lib/python3.10/dist-packages/sklearn/base.py:439: UserWarning: X does not have valid feature names, but RandomForestClassifier was fitted with feature names\n",
            "  warnings.warn(\n",
            "[0]\n",
            "/usr/local/lib/python3.10/dist-packages/sklearn/base.py:439: UserWarning: X does not have valid feature names, but RandomForestClassifier was fitted with feature names\n",
            "  warnings.warn(\n",
            "2024-07-02 16:09:27.524 Uncaught app exception\n",
            "Traceback (most recent call last):\n",
            "  File \"/usr/local/lib/python3.10/dist-packages/streamlit/runtime/scriptrunner/script_runner.py\", line 589, in _run_script\n",
            "    exec(code, module.__dict__)\n",
            "  File \"/content/web.py\", line 59, in <module>\n",
            "    main()\n",
            "  File \"/content/web.py\", line 54, in main\n",
            "    survive=survival_prediction([Age,SibSp,Pclass,Parch,PassengerId,Sex,Fare,Embarked])\n",
            "  File \"/content/web.py\", line 18, in survival_prediction\n",
            "    prediction=model.predict(b)\n",
            "  File \"/usr/local/lib/python3.10/dist-packages/sklearn/ensemble/_forest.py\", line 820, in predict\n",
            "    proba = self.predict_proba(X)\n",
            "  File \"/usr/local/lib/python3.10/dist-packages/sklearn/ensemble/_forest.py\", line 862, in predict_proba\n",
            "    X = self._validate_X_predict(X)\n",
            "  File \"/usr/local/lib/python3.10/dist-packages/sklearn/ensemble/_forest.py\", line 602, in _validate_X_predict\n",
            "    X = self._validate_data(X, dtype=DTYPE, accept_sparse=\"csr\", reset=False)\n",
            "  File \"/usr/local/lib/python3.10/dist-packages/sklearn/base.py\", line 565, in _validate_data\n",
            "    X = check_array(X, input_name=\"X\", **check_params)\n",
            "  File \"/usr/local/lib/python3.10/dist-packages/sklearn/utils/validation.py\", line 879, in check_array\n",
            "    array = _asarray_with_order(array, order=order, dtype=dtype, xp=xp)\n",
            "  File \"/usr/local/lib/python3.10/dist-packages/sklearn/utils/_array_api.py\", line 185, in _asarray_with_order\n",
            "    array = numpy.asarray(array, order=order, dtype=dtype)\n",
            "ValueError: could not convert string to float: 'Male'\n",
            "/usr/local/lib/python3.10/dist-packages/sklearn/base.py:439: UserWarning: X does not have valid feature names, but RandomForestClassifier was fitted with feature names\n",
            "  warnings.warn(\n",
            "[0]\n",
            "/usr/local/lib/python3.10/dist-packages/sklearn/base.py:439: UserWarning: X does not have valid feature names, but RandomForestClassifier was fitted with feature names\n",
            "  warnings.warn(\n",
            "2024-07-02 16:12:38.068 Uncaught app exception\n",
            "Traceback (most recent call last):\n",
            "  File \"/usr/local/lib/python3.10/dist-packages/streamlit/runtime/scriptrunner/script_runner.py\", line 589, in _run_script\n",
            "    exec(code, module.__dict__)\n",
            "  File \"/content/web.py\", line 59, in <module>\n",
            "    main()\n",
            "  File \"/content/web.py\", line 54, in main\n",
            "    survive=survival_prediction([Age,SibSp,Pclass,Parch,PassengerId,Sex,Fare,Embarked])\n",
            "  File \"/content/web.py\", line 18, in survival_prediction\n",
            "    prediction=model.predict(b)\n",
            "  File \"/usr/local/lib/python3.10/dist-packages/sklearn/ensemble/_forest.py\", line 820, in predict\n",
            "    proba = self.predict_proba(X)\n",
            "  File \"/usr/local/lib/python3.10/dist-packages/sklearn/ensemble/_forest.py\", line 862, in predict_proba\n",
            "    X = self._validate_X_predict(X)\n",
            "  File \"/usr/local/lib/python3.10/dist-packages/sklearn/ensemble/_forest.py\", line 602, in _validate_X_predict\n",
            "    X = self._validate_data(X, dtype=DTYPE, accept_sparse=\"csr\", reset=False)\n",
            "  File \"/usr/local/lib/python3.10/dist-packages/sklearn/base.py\", line 565, in _validate_data\n",
            "    X = check_array(X, input_name=\"X\", **check_params)\n",
            "  File \"/usr/local/lib/python3.10/dist-packages/sklearn/utils/validation.py\", line 879, in check_array\n",
            "    array = _asarray_with_order(array, order=order, dtype=dtype, xp=xp)\n",
            "  File \"/usr/local/lib/python3.10/dist-packages/sklearn/utils/_array_api.py\", line 185, in _asarray_with_order\n",
            "    array = numpy.asarray(array, order=order, dtype=dtype)\n",
            "ValueError: could not convert string to float: 'Male'\n",
            "/usr/local/lib/python3.10/dist-packages/sklearn/base.py:439: UserWarning: X does not have valid feature names, but KNeighborsClassifier was fitted with feature names\n",
            "  warnings.warn(\n",
            "2024-07-02 16:14:09.684 Uncaught app exception\n",
            "Traceback (most recent call last):\n",
            "  File \"/usr/local/lib/python3.10/dist-packages/streamlit/runtime/scriptrunner/script_runner.py\", line 589, in _run_script\n",
            "    exec(code, module.__dict__)\n",
            "  File \"/content/web.py\", line 57, in <module>\n",
            "    main()\n",
            "  File \"/content/web.py\", line 52, in main\n",
            "    survive=survival_prediction([Age,SibSp,Pclass,Parch,PassengerId,Sex,Fare,Embarked])\n",
            "  File \"/content/web.py\", line 16, in survival_prediction\n",
            "    prediction=model.predict(b)\n",
            "  File \"/usr/local/lib/python3.10/dist-packages/sklearn/neighbors/_classification.py\", line 234, in predict\n",
            "    neigh_ind = self.kneighbors(X, return_distance=False)\n",
            "  File \"/usr/local/lib/python3.10/dist-packages/sklearn/neighbors/_base.py\", line 806, in kneighbors\n",
            "    X = self._validate_data(X, accept_sparse=\"csr\", reset=False, order=\"C\")\n",
            "  File \"/usr/local/lib/python3.10/dist-packages/sklearn/base.py\", line 565, in _validate_data\n",
            "    X = check_array(X, input_name=\"X\", **check_params)\n",
            "  File \"/usr/local/lib/python3.10/dist-packages/sklearn/utils/validation.py\", line 910, in check_array\n",
            "    raise ValueError(\n",
            "ValueError: dtype='numeric' is not compatible with arrays of bytes/strings.Convert your data to numeric values explicitly instead.\n",
            "/usr/local/lib/python3.10/dist-packages/sklearn/base.py:439: UserWarning: X does not have valid feature names, but KNeighborsClassifier was fitted with feature names\n",
            "  warnings.warn(\n",
            "2024-07-02 16:15:15.770 Uncaught app exception\n",
            "Traceback (most recent call last):\n",
            "  File \"/usr/local/lib/python3.10/dist-packages/streamlit/runtime/scriptrunner/script_runner.py\", line 589, in _run_script\n",
            "    exec(code, module.__dict__)\n",
            "  File \"/content/web.py\", line 58, in <module>\n",
            "    main()\n",
            "  File \"/content/web.py\", line 53, in main\n",
            "    survive=survival_prediction([Age,SibSp,Pclass,Parch,PassengerId,Sex,Fare,Embarked])\n",
            "  File \"/content/web.py\", line 17, in survival_prediction\n",
            "    prediction=model.predict(b)\n",
            "  File \"/usr/local/lib/python3.10/dist-packages/sklearn/neighbors/_classification.py\", line 234, in predict\n",
            "    neigh_ind = self.kneighbors(X, return_distance=False)\n",
            "  File \"/usr/local/lib/python3.10/dist-packages/sklearn/neighbors/_base.py\", line 806, in kneighbors\n",
            "    X = self._validate_data(X, accept_sparse=\"csr\", reset=False, order=\"C\")\n",
            "  File \"/usr/local/lib/python3.10/dist-packages/sklearn/base.py\", line 565, in _validate_data\n",
            "    X = check_array(X, input_name=\"X\", **check_params)\n",
            "  File \"/usr/local/lib/python3.10/dist-packages/sklearn/utils/validation.py\", line 910, in check_array\n",
            "    raise ValueError(\n",
            "ValueError: dtype='numeric' is not compatible with arrays of bytes/strings.Convert your data to numeric values explicitly instead.\n",
            "/usr/local/lib/python3.10/dist-packages/sklearn/base.py:439: UserWarning: X does not have valid feature names, but KNeighborsClassifier was fitted with feature names\n",
            "  warnings.warn(\n",
            "2024-07-02 16:16:28.488 Uncaught app exception\n",
            "Traceback (most recent call last):\n",
            "  File \"/usr/local/lib/python3.10/dist-packages/streamlit/runtime/scriptrunner/script_runner.py\", line 589, in _run_script\n",
            "    exec(code, module.__dict__)\n",
            "  File \"/content/web.py\", line 58, in <module>\n",
            "    main()\n",
            "  File \"/content/web.py\", line 53, in main\n",
            "    survive=survival_prediction([Age,SibSp,Pclass,Parch,PassengerId,Sex,Fare,Embarked])\n",
            "  File \"/content/web.py\", line 17, in survival_prediction\n",
            "    prediction=model.predict(b)\n",
            "  File \"/usr/local/lib/python3.10/dist-packages/sklearn/neighbors/_classification.py\", line 234, in predict\n",
            "    neigh_ind = self.kneighbors(X, return_distance=False)\n",
            "  File \"/usr/local/lib/python3.10/dist-packages/sklearn/neighbors/_base.py\", line 806, in kneighbors\n",
            "    X = self._validate_data(X, accept_sparse=\"csr\", reset=False, order=\"C\")\n",
            "  File \"/usr/local/lib/python3.10/dist-packages/sklearn/base.py\", line 565, in _validate_data\n",
            "    X = check_array(X, input_name=\"X\", **check_params)\n",
            "  File \"/usr/local/lib/python3.10/dist-packages/sklearn/utils/validation.py\", line 910, in check_array\n",
            "    raise ValueError(\n",
            "ValueError: dtype='numeric' is not compatible with arrays of bytes/strings.Convert your data to numeric values explicitly instead.\n",
            "2024-07-02 16:19:22.569 Uncaught app exception\n",
            "Traceback (most recent call last):\n",
            "  File \"/usr/local/lib/python3.10/dist-packages/streamlit/runtime/scriptrunner/script_runner.py\", line 589, in _run_script\n",
            "    exec(code, module.__dict__)\n",
            "  File \"/content/web.py\", line 7, in <module>\n",
            "    model=joblib.read('KNN.joblib')\n",
            "AttributeError: module 'joblib' has no attribute 'read'\n",
            "2024-07-02 16:38:43.098 Uncaught app exception\n",
            "Traceback (most recent call last):\n",
            "  File \"/usr/local/lib/python3.10/dist-packages/streamlit/runtime/scriptrunner/script_runner.py\", line 589, in _run_script\n",
            "    exec(code, module.__dict__)\n",
            "  File \"/content/web.py\", line 57, in <module>\n",
            "    main()\n",
            "  File \"/content/web.py\", line 33, in main\n",
            "    Sex=st.selectbox('select option')\n",
            "  File \"/usr/local/lib/python3.10/dist-packages/streamlit/runtime/metrics_util.py\", line 408, in wrapped_func\n",
            "    result = non_optional_func(*args, **kwargs)\n",
            "TypeError: SelectboxMixin.selectbox() missing 1 required positional argument: 'options'\n",
            "/usr/local/lib/python3.10/dist-packages/sklearn/base.py:439: UserWarning: X does not have valid feature names, but KNeighborsClassifier was fitted with feature names\n",
            "  warnings.warn(\n",
            "2024-07-02 16:39:46.044 Uncaught app exception\n",
            "Traceback (most recent call last):\n",
            "  File \"/usr/local/lib/python3.10/dist-packages/streamlit/runtime/scriptrunner/script_runner.py\", line 589, in _run_script\n",
            "    exec(code, module.__dict__)\n",
            "  File \"/content/web.py\", line 57, in <module>\n",
            "    main()\n",
            "  File \"/content/web.py\", line 52, in main\n",
            "    survive=survival_prediction([Age,SibSp,Pclass,Parch,PassengerId,Sex,Fare,Embarked])\n",
            "  File \"/content/web.py\", line 17, in survival_prediction\n",
            "    prediction=model.predict(b)\n",
            "  File \"/usr/local/lib/python3.10/dist-packages/sklearn/neighbors/_classification.py\", line 234, in predict\n",
            "    neigh_ind = self.kneighbors(X, return_distance=False)\n",
            "  File \"/usr/local/lib/python3.10/dist-packages/sklearn/neighbors/_base.py\", line 806, in kneighbors\n",
            "    X = self._validate_data(X, accept_sparse=\"csr\", reset=False, order=\"C\")\n",
            "  File \"/usr/local/lib/python3.10/dist-packages/sklearn/base.py\", line 565, in _validate_data\n",
            "    X = check_array(X, input_name=\"X\", **check_params)\n",
            "  File \"/usr/local/lib/python3.10/dist-packages/sklearn/utils/validation.py\", line 910, in check_array\n",
            "    raise ValueError(\n",
            "ValueError: dtype='numeric' is not compatible with arrays of bytes/strings.Convert your data to numeric values explicitly instead.\n",
            "/usr/local/lib/python3.10/dist-packages/sklearn/base.py:439: UserWarning: X does not have valid feature names, but KNeighborsClassifier was fitted with feature names\n",
            "  warnings.warn(\n",
            "2024-07-02 16:40:54.624 Uncaught app exception\n",
            "Traceback (most recent call last):\n",
            "  File \"/usr/local/lib/python3.10/dist-packages/streamlit/runtime/scriptrunner/script_runner.py\", line 589, in _run_script\n",
            "    exec(code, module.__dict__)\n",
            "  File \"/content/web.py\", line 57, in <module>\n",
            "    main()\n",
            "  File \"/content/web.py\", line 52, in main\n",
            "    survive=survival_prediction([Age,SibSp,Pclass,Parch,PassengerId,Sex,Fare,Embarked])\n",
            "  File \"/content/web.py\", line 17, in survival_prediction\n",
            "    prediction=model.predict(b)\n",
            "  File \"/usr/local/lib/python3.10/dist-packages/sklearn/neighbors/_classification.py\", line 234, in predict\n",
            "    neigh_ind = self.kneighbors(X, return_distance=False)\n",
            "  File \"/usr/local/lib/python3.10/dist-packages/sklearn/neighbors/_base.py\", line 806, in kneighbors\n",
            "    X = self._validate_data(X, accept_sparse=\"csr\", reset=False, order=\"C\")\n",
            "  File \"/usr/local/lib/python3.10/dist-packages/sklearn/base.py\", line 565, in _validate_data\n",
            "    X = check_array(X, input_name=\"X\", **check_params)\n",
            "  File \"/usr/local/lib/python3.10/dist-packages/sklearn/utils/validation.py\", line 910, in check_array\n",
            "    raise ValueError(\n",
            "ValueError: dtype='numeric' is not compatible with arrays of bytes/strings.Convert your data to numeric values explicitly instead.\n",
            "/usr/local/lib/python3.10/dist-packages/sklearn/base.py:439: UserWarning: X does not have valid feature names, but RandomForestClassifier was fitted with feature names\n",
            "  warnings.warn(\n",
            "2024-07-02 16:51:40.817 Uncaught app exception\n",
            "Traceback (most recent call last):\n",
            "  File \"/usr/local/lib/python3.10/dist-packages/streamlit/runtime/scriptrunner/script_runner.py\", line 589, in _run_script\n",
            "    exec(code, module.__dict__)\n",
            "  File \"/content/web.py\", line 57, in <module>\n",
            "    main()\n",
            "  File \"/content/web.py\", line 52, in main\n",
            "    survive=survival_prediction([Age,SibSp,Pclass,Parch,PassengerId,Sex,Fare,Embarked])\n",
            "  File \"/content/web.py\", line 17, in survival_prediction\n",
            "    prediction=model.predict(b)\n",
            "  File \"/usr/local/lib/python3.10/dist-packages/sklearn/ensemble/_forest.py\", line 820, in predict\n",
            "    proba = self.predict_proba(X)\n",
            "  File \"/usr/local/lib/python3.10/dist-packages/sklearn/ensemble/_forest.py\", line 862, in predict_proba\n",
            "    X = self._validate_X_predict(X)\n",
            "  File \"/usr/local/lib/python3.10/dist-packages/sklearn/ensemble/_forest.py\", line 602, in _validate_X_predict\n",
            "    X = self._validate_data(X, dtype=DTYPE, accept_sparse=\"csr\", reset=False)\n",
            "  File \"/usr/local/lib/python3.10/dist-packages/sklearn/base.py\", line 565, in _validate_data\n",
            "    X = check_array(X, input_name=\"X\", **check_params)\n",
            "  File \"/usr/local/lib/python3.10/dist-packages/sklearn/utils/validation.py\", line 879, in check_array\n",
            "    array = _asarray_with_order(array, order=order, dtype=dtype, xp=xp)\n",
            "  File \"/usr/local/lib/python3.10/dist-packages/sklearn/utils/_array_api.py\", line 185, in _asarray_with_order\n",
            "    array = numpy.asarray(array, order=order, dtype=dtype)\n",
            "ValueError: could not convert string to float: 'Female'\n",
            "/usr/local/lib/python3.10/dist-packages/sklearn/base.py:439: UserWarning: X does not have valid feature names, but RandomForestClassifier was fitted with feature names\n",
            "  warnings.warn(\n",
            "2024-07-02 16:54:47.186 Uncaught app exception\n",
            "Traceback (most recent call last):\n",
            "  File \"/usr/local/lib/python3.10/dist-packages/streamlit/runtime/scriptrunner/script_runner.py\", line 589, in _run_script\n",
            "    exec(code, module.__dict__)\n",
            "  File \"/content/web.py\", line 57, in <module>\n",
            "    main()\n",
            "  File \"/content/web.py\", line 52, in main\n",
            "    survive=survival_prediction([Age,SibSp,Pclass,Parch,PassengerId,Sex,Fare,Embarked])\n",
            "  File \"/content/web.py\", line 17, in survival_prediction\n",
            "    prediction=model.predict(b)\n",
            "  File \"/usr/local/lib/python3.10/dist-packages/sklearn/ensemble/_forest.py\", line 820, in predict\n",
            "    proba = self.predict_proba(X)\n",
            "  File \"/usr/local/lib/python3.10/dist-packages/sklearn/ensemble/_forest.py\", line 862, in predict_proba\n",
            "    X = self._validate_X_predict(X)\n",
            "  File \"/usr/local/lib/python3.10/dist-packages/sklearn/ensemble/_forest.py\", line 602, in _validate_X_predict\n",
            "    X = self._validate_data(X, dtype=DTYPE, accept_sparse=\"csr\", reset=False)\n",
            "  File \"/usr/local/lib/python3.10/dist-packages/sklearn/base.py\", line 565, in _validate_data\n",
            "    X = check_array(X, input_name=\"X\", **check_params)\n",
            "  File \"/usr/local/lib/python3.10/dist-packages/sklearn/utils/validation.py\", line 879, in check_array\n",
            "    array = _asarray_with_order(array, order=order, dtype=dtype, xp=xp)\n",
            "  File \"/usr/local/lib/python3.10/dist-packages/sklearn/utils/_array_api.py\", line 185, in _asarray_with_order\n",
            "    array = numpy.asarray(array, order=order, dtype=dtype)\n",
            "ValueError: could not convert string to float: 'Male'\n",
            "/usr/local/lib/python3.10/dist-packages/sklearn/base.py:439: UserWarning: X does not have valid feature names, but RandomForestClassifier was fitted with feature names\n",
            "  warnings.warn(\n",
            "2024-07-02 16:55:33.359 Uncaught app exception\n",
            "Traceback (most recent call last):\n",
            "  File \"/usr/local/lib/python3.10/dist-packages/streamlit/runtime/scriptrunner/script_runner.py\", line 589, in _run_script\n",
            "    exec(code, module.__dict__)\n",
            "  File \"/content/web.py\", line 57, in <module>\n",
            "    main()\n",
            "  File \"/content/web.py\", line 52, in main\n",
            "    survive=survival_prediction([Age,SibSp,Pclass,Parch,PassengerId,Sex,Fare,Embarked])\n",
            "  File \"/content/web.py\", line 17, in survival_prediction\n",
            "    prediction=model.predict(b)\n",
            "  File \"/usr/local/lib/python3.10/dist-packages/sklearn/ensemble/_forest.py\", line 820, in predict\n",
            "    proba = self.predict_proba(X)\n",
            "  File \"/usr/local/lib/python3.10/dist-packages/sklearn/ensemble/_forest.py\", line 862, in predict_proba\n",
            "    X = self._validate_X_predict(X)\n",
            "  File \"/usr/local/lib/python3.10/dist-packages/sklearn/ensemble/_forest.py\", line 602, in _validate_X_predict\n",
            "    X = self._validate_data(X, dtype=DTYPE, accept_sparse=\"csr\", reset=False)\n",
            "  File \"/usr/local/lib/python3.10/dist-packages/sklearn/base.py\", line 565, in _validate_data\n",
            "    X = check_array(X, input_name=\"X\", **check_params)\n",
            "  File \"/usr/local/lib/python3.10/dist-packages/sklearn/utils/validation.py\", line 879, in check_array\n",
            "    array = _asarray_with_order(array, order=order, dtype=dtype, xp=xp)\n",
            "  File \"/usr/local/lib/python3.10/dist-packages/sklearn/utils/_array_api.py\", line 185, in _asarray_with_order\n",
            "    array = numpy.asarray(array, order=order, dtype=dtype)\n",
            "ValueError: could not convert string to float: 'Male'\n",
            "/usr/local/lib/python3.10/dist-packages/sklearn/base.py:439: UserWarning: X does not have valid feature names, but RandomForestClassifier was fitted with feature names\n",
            "  warnings.warn(\n",
            "2024-07-02 17:01:12.130 Uncaught app exception\n",
            "Traceback (most recent call last):\n",
            "  File \"/usr/local/lib/python3.10/dist-packages/streamlit/runtime/scriptrunner/script_runner.py\", line 589, in _run_script\n",
            "    exec(code, module.__dict__)\n",
            "  File \"/content/web.py\", line 57, in <module>\n",
            "    main()\n",
            "  File \"/content/web.py\", line 52, in main\n",
            "    survive=survival_prediction([Age,SibSp,Pclass,Parch,PassengerId,Sex,Fare,Embarked])\n",
            "  File \"/content/web.py\", line 17, in survival_prediction\n",
            "    prediction=model.predict(b)\n",
            "  File \"/usr/local/lib/python3.10/dist-packages/sklearn/ensemble/_forest.py\", line 820, in predict\n",
            "    proba = self.predict_proba(X)\n",
            "  File \"/usr/local/lib/python3.10/dist-packages/sklearn/ensemble/_forest.py\", line 862, in predict_proba\n",
            "    X = self._validate_X_predict(X)\n",
            "  File \"/usr/local/lib/python3.10/dist-packages/sklearn/ensemble/_forest.py\", line 602, in _validate_X_predict\n",
            "    X = self._validate_data(X, dtype=DTYPE, accept_sparse=\"csr\", reset=False)\n",
            "  File \"/usr/local/lib/python3.10/dist-packages/sklearn/base.py\", line 565, in _validate_data\n",
            "    X = check_array(X, input_name=\"X\", **check_params)\n",
            "  File \"/usr/local/lib/python3.10/dist-packages/sklearn/utils/validation.py\", line 879, in check_array\n",
            "    array = _asarray_with_order(array, order=order, dtype=dtype, xp=xp)\n",
            "  File \"/usr/local/lib/python3.10/dist-packages/sklearn/utils/_array_api.py\", line 185, in _asarray_with_order\n",
            "    array = numpy.asarray(array, order=order, dtype=dtype)\n",
            "ValueError: could not convert string to float: 'Male'\n",
            "2024-07-02 17:11:43.328 Uncaught app exception\n",
            "Traceback (most recent call last):\n",
            "  File \"/usr/local/lib/python3.10/dist-packages/streamlit/runtime/scriptrunner/script_runner.py\", line 589, in _run_script\n",
            "    exec(code, module.__dict__)\n",
            "  File \"/content/web.py\", line 57, in <module>\n",
            "    main()\n",
            "  File \"/content/web.py\", line 36, in main\n",
            "    Embarked=st.text_input('Embarked',a.classes_)\n",
            "  File \"/usr/local/lib/python3.10/dist-packages/streamlit/runtime/metrics_util.py\", line 408, in wrapped_func\n",
            "    result = non_optional_func(*args, **kwargs)\n",
            "  File \"/usr/local/lib/python3.10/dist-packages/streamlit/elements/widgets/text_widgets.py\", line 227, in text_input\n",
            "    return self._text_input(\n",
            "  File \"/usr/local/lib/python3.10/dist-packages/streamlit/elements/widgets/text_widgets.py\", line 267, in _text_input\n",
            "    check_session_state_rules(default_value=None if value == \"\" else value, key=key)\n",
            "ValueError: The truth value of an array with more than one element is ambiguous. Use a.any() or a.all()\n",
            "/usr/local/lib/python3.10/dist-packages/sklearn/base.py:439: UserWarning: X does not have valid feature names, but RandomForestClassifier was fitted with feature names\n",
            "  warnings.warn(\n",
            "2024-07-02 17:15:41.734 Uncaught app exception\n",
            "Traceback (most recent call last):\n",
            "  File \"/usr/local/lib/python3.10/dist-packages/streamlit/runtime/scriptrunner/script_runner.py\", line 589, in _run_script\n",
            "    exec(code, module.__dict__)\n",
            "  File \"/content/web.py\", line 58, in <module>\n",
            "    main()\n",
            "  File \"/content/web.py\", line 53, in main\n",
            "    survive=survival_prediction([Age,SibSp,Pclass,Parch,PassengerId,Sex,Fare,Embarked])\n",
            "  File \"/content/web.py\", line 17, in survival_prediction\n",
            "    prediction=model.predict(b)\n",
            "  File \"/usr/local/lib/python3.10/dist-packages/sklearn/ensemble/_forest.py\", line 820, in predict\n",
            "    proba = self.predict_proba(X)\n",
            "  File \"/usr/local/lib/python3.10/dist-packages/sklearn/ensemble/_forest.py\", line 862, in predict_proba\n",
            "    X = self._validate_X_predict(X)\n",
            "  File \"/usr/local/lib/python3.10/dist-packages/sklearn/ensemble/_forest.py\", line 602, in _validate_X_predict\n",
            "    X = self._validate_data(X, dtype=DTYPE, accept_sparse=\"csr\", reset=False)\n",
            "  File \"/usr/local/lib/python3.10/dist-packages/sklearn/base.py\", line 565, in _validate_data\n",
            "    X = check_array(X, input_name=\"X\", **check_params)\n",
            "  File \"/usr/local/lib/python3.10/dist-packages/sklearn/utils/validation.py\", line 879, in check_array\n",
            "    array = _asarray_with_order(array, order=order, dtype=dtype, xp=xp)\n",
            "  File \"/usr/local/lib/python3.10/dist-packages/sklearn/utils/_array_api.py\", line 185, in _asarray_with_order\n",
            "    array = numpy.asarray(array, order=order, dtype=dtype)\n",
            "ValueError: could not convert string to float: 'Male'\n",
            "/usr/local/lib/python3.10/dist-packages/sklearn/base.py:439: UserWarning: X does not have valid feature names, but RandomForestClassifier was fitted with feature names\n",
            "  warnings.warn(\n",
            "2024-07-02 17:16:11.576 Uncaught app exception\n",
            "Traceback (most recent call last):\n",
            "  File \"/usr/local/lib/python3.10/dist-packages/streamlit/runtime/scriptrunner/script_runner.py\", line 589, in _run_script\n",
            "    exec(code, module.__dict__)\n",
            "  File \"/content/web.py\", line 58, in <module>\n",
            "    main()\n",
            "  File \"/content/web.py\", line 53, in main\n",
            "    survive=survival_prediction([Age,SibSp,Pclass,Parch,PassengerId,Sex,Fare,Embarked])\n",
            "  File \"/content/web.py\", line 17, in survival_prediction\n",
            "    prediction=model.predict(b)\n",
            "  File \"/usr/local/lib/python3.10/dist-packages/sklearn/ensemble/_forest.py\", line 820, in predict\n",
            "    proba = self.predict_proba(X)\n",
            "  File \"/usr/local/lib/python3.10/dist-packages/sklearn/ensemble/_forest.py\", line 862, in predict_proba\n",
            "    X = self._validate_X_predict(X)\n",
            "  File \"/usr/local/lib/python3.10/dist-packages/sklearn/ensemble/_forest.py\", line 602, in _validate_X_predict\n",
            "    X = self._validate_data(X, dtype=DTYPE, accept_sparse=\"csr\", reset=False)\n",
            "  File \"/usr/local/lib/python3.10/dist-packages/sklearn/base.py\", line 565, in _validate_data\n",
            "    X = check_array(X, input_name=\"X\", **check_params)\n",
            "  File \"/usr/local/lib/python3.10/dist-packages/sklearn/utils/validation.py\", line 879, in check_array\n",
            "    array = _asarray_with_order(array, order=order, dtype=dtype, xp=xp)\n",
            "  File \"/usr/local/lib/python3.10/dist-packages/sklearn/utils/_array_api.py\", line 185, in _asarray_with_order\n",
            "    array = numpy.asarray(array, order=order, dtype=dtype)\n",
            "ValueError: could not convert string to float: 'Male'\n",
            "2024-07-02 17:31:14.043 Uncaught app exception\n",
            "Traceback (most recent call last):\n",
            "  File \"/usr/local/lib/python3.10/dist-packages/streamlit/runtime/scriptrunner/script_runner.py\", line 589, in _run_script\n",
            "    exec(code, module.__dict__)\n",
            "  File \"/content/web.py\", line 57, in <module>\n",
            "    main()\n",
            "  File \"/content/web.py\", line 34, in main\n",
            "    Embarked=st.select('Embarked')\n",
            "AttributeError: module 'streamlit' has no attribute 'select'\n",
            "2024-07-02 17:32:28.969 Uncaught app exception\n",
            "Traceback (most recent call last):\n",
            "  File \"/usr/local/lib/python3.10/dist-packages/streamlit/runtime/scriptrunner/script_runner.py\", line 589, in _run_script\n",
            "    exec(code, module.__dict__)\n",
            "  File \"/content/web.py\", line 55, in <module>\n",
            "    main()\n",
            "  File \"/content/web.py\", line 34, in main\n",
            "    Embarked=st.select('Embarked')\n",
            "AttributeError: module 'streamlit' has no attribute 'select'\n",
            "2024-07-02 17:32:36.914 Uncaught app exception\n",
            "Traceback (most recent call last):\n",
            "  File \"/usr/local/lib/python3.10/dist-packages/streamlit/runtime/scriptrunner/script_runner.py\", line 589, in _run_script\n",
            "    exec(code, module.__dict__)\n",
            "  File \"/content/web.py\", line 55, in <module>\n",
            "    main()\n",
            "  File \"/content/web.py\", line 34, in main\n",
            "    Embarked=st.select('Embarked')\n",
            "AttributeError: module 'streamlit' has no attribute 'select'\n",
            "2024-07-02 17:32:43.145 Uncaught app exception\n",
            "Traceback (most recent call last):\n",
            "  File \"/usr/local/lib/python3.10/dist-packages/streamlit/runtime/scriptrunner/script_runner.py\", line 589, in _run_script\n",
            "    exec(code, module.__dict__)\n",
            "  File \"/content/web.py\", line 55, in <module>\n",
            "    main()\n",
            "  File \"/content/web.py\", line 34, in main\n",
            "    Embarked=st.selectbpx('Embarked')\n",
            "AttributeError: module 'streamlit' has no attribute 'selectbpx'\n",
            "2024-07-02 17:32:44.075 Uncaught app exception\n",
            "Traceback (most recent call last):\n",
            "  File \"/usr/local/lib/python3.10/dist-packages/streamlit/runtime/scriptrunner/script_runner.py\", line 589, in _run_script\n",
            "    exec(code, module.__dict__)\n",
            "  File \"/content/web.py\", line 55, in <module>\n",
            "    main()\n",
            "  File \"/content/web.py\", line 34, in main\n",
            "    Embarked=st.selectbpx('Embarked')\n",
            "AttributeError: module 'streamlit' has no attribute 'selectbpx'\n",
            "2024-07-02 17:33:13.155 Uncaught app exception\n",
            "Traceback (most recent call last):\n",
            "  File \"/usr/local/lib/python3.10/dist-packages/streamlit/runtime/scriptrunner/script_runner.py\", line 589, in _run_script\n",
            "    exec(code, module.__dict__)\n",
            "  File \"/content/web.py\", line 55, in <module>\n",
            "    main()\n",
            "  File \"/content/web.py\", line 34, in main\n",
            "    Embarked=st.selectbox('Embarked')\n",
            "  File \"/usr/local/lib/python3.10/dist-packages/streamlit/runtime/metrics_util.py\", line 408, in wrapped_func\n",
            "    result = non_optional_func(*args, **kwargs)\n",
            "TypeError: SelectboxMixin.selectbox() missing 1 required positional argument: 'options'\n",
            "2024-07-02 17:33:54.630 Uncaught app exception\n",
            "Traceback (most recent call last):\n",
            "  File \"/usr/local/lib/python3.10/dist-packages/streamlit/runtime/scriptrunner/script_runner.py\", line 589, in _run_script\n",
            "    exec(code, module.__dict__)\n",
            "  File \"/content/web.py\", line 55, in <module>\n",
            "    main()\n",
            "  File \"/content/web.py\", line 34, in main\n",
            "    Embarked=st.selectbox('Embarked',)\n",
            "  File \"/usr/local/lib/python3.10/dist-packages/streamlit/runtime/metrics_util.py\", line 408, in wrapped_func\n",
            "    result = non_optional_func(*args, **kwargs)\n",
            "TypeError: SelectboxMixin.selectbox() missing 1 required positional argument: 'options'\n",
            "2024-07-02 17:34:45.951 Uncaught app exception\n",
            "Traceback (most recent call last):\n",
            "  File \"/usr/local/lib/python3.10/dist-packages/streamlit/runtime/scriptrunner/script_runner.py\", line 589, in _run_script\n",
            "    exec(code, module.__dict__)\n",
            "  File \"/content/web.py\", line 55, in <module>\n",
            "    main()\n",
            "  File \"/content/web.py\", line 34, in main\n",
            "    Embarked=st.selectbox('Embarked',)\n",
            "  File \"/usr/local/lib/python3.10/dist-packages/streamlit/runtime/metrics_util.py\", line 408, in wrapped_func\n",
            "    result = non_optional_func(*args, **kwargs)\n",
            "TypeError: SelectboxMixin.selectbox() missing 1 required positional argument: 'options'\n",
            "2024-07-02 17:53:48.703 Uncaught app exception\n",
            "Traceback (most recent call last):\n",
            "  File \"/usr/local/lib/python3.10/dist-packages/streamlit/runtime/scriptrunner/script_runner.py\", line 589, in _run_script\n",
            "    exec(code, module.__dict__)\n",
            "  File \"/content/web.py\", line 56, in <module>\n",
            "    main()\n",
            "  File \"/content/web.py\", line 33, in main\n",
            "    Sex=sex_encoder\n",
            "NameError: name 'sex_encoder' is not defined\n",
            "2024-07-02 17:53:56.939 Uncaught app exception\n",
            "Traceback (most recent call last):\n",
            "  File \"/usr/local/lib/python3.10/dist-packages/streamlit/runtime/scriptrunner/script_runner.py\", line 589, in _run_script\n",
            "    exec(code, module.__dict__)\n",
            "  File \"/content/web.py\", line 56, in <module>\n",
            "    main()\n",
            "  File \"/content/web.py\", line 33, in main\n",
            "    Sex=sex_encoder.fit_transform\n",
            "NameError: name 'sex_encoder' is not defined\n",
            "2024-07-02 17:54:01.511 Uncaught app exception\n",
            "Traceback (most recent call last):\n",
            "  File \"/usr/local/lib/python3.10/dist-packages/streamlit/runtime/scriptrunner/script_runner.py\", line 589, in _run_script\n",
            "    exec(code, module.__dict__)\n",
            "  File \"/content/web.py\", line 56, in <module>\n",
            "    main()\n",
            "  File \"/content/web.py\", line 33, in main\n",
            "    Sex=sex_encoder.fit_transform([])\n",
            "NameError: name 'sex_encoder' is not defined\n",
            "2024-07-02 17:54:04.998 Uncaught app exception\n",
            "Traceback (most recent call last):\n",
            "  File \"/usr/local/lib/python3.10/dist-packages/streamlit/runtime/scriptrunner/script_runner.py\", line 589, in _run_script\n",
            "    exec(code, module.__dict__)\n",
            "  File \"/content/web.py\", line 56, in <module>\n",
            "    main()\n",
            "  File \"/content/web.py\", line 33, in main\n",
            "    Sex=sex_encoder.fit_transform([Sex])\n",
            "NameError: name 'sex_encoder' is not defined\n",
            "2024-07-02 17:54:13.167 Uncaught app exception\n",
            "Traceback (most recent call last):\n",
            "  File \"/usr/local/lib/python3.10/dist-packages/streamlit/runtime/scriptrunner/script_runner.py\", line 589, in _run_script\n",
            "    exec(code, module.__dict__)\n",
            "  File \"/content/web.py\", line 56, in <module>\n",
            "    main()\n",
            "  File \"/content/web.py\", line 33, in main\n",
            "    Sex=sex_encoder.fit_transform([Sex])[0]\n",
            "NameError: name 'sex_encoder' is not defined\n",
            "2024-07-02 17:54:20.251 Uncaught app exception\n",
            "Traceback (most recent call last):\n",
            "  File \"/usr/local/lib/python3.10/dist-packages/streamlit/runtime/scriptrunner/script_runner.py\", line 589, in _run_script\n",
            "    exec(code, module.__dict__)\n",
            "  File \"/content/web.py\", line 58, in <module>\n",
            "    main()\n",
            "  File \"/content/web.py\", line 33, in main\n",
            "    Sex=sex_encoder.fit_transform([Sex])[0]\n",
            "NameError: name 'sex_encoder' is not defined\n",
            "2024-07-02 17:54:43.183 Uncaught app exception\n",
            "Traceback (most recent call last):\n",
            "  File \"/usr/local/lib/python3.10/dist-packages/streamlit/runtime/scriptrunner/script_runner.py\", line 589, in _run_script\n",
            "    exec(code, module.__dict__)\n",
            "  File \"/content/web.py\", line 58, in <module>\n",
            "    main()\n",
            "  File \"/content/web.py\", line 33, in main\n",
            "    Sex=sex_encoder.fit_transform([Sex])[0]\n",
            "NameError: name 'sex_encoder' is not defined\n",
            "2024-07-02 17:54:43.929 Uncaught app exception\n",
            "Traceback (most recent call last):\n",
            "  File \"/usr/local/lib/python3.10/dist-packages/streamlit/runtime/scriptrunner/script_runner.py\", line 589, in _run_script\n",
            "    exec(code, module.__dict__)\n",
            "  File \"/content/web.py\", line 58, in <module>\n",
            "    main()\n",
            "  File \"/content/web.py\", line 33, in main\n",
            "    Sex=sex_encoder.fit_transform([Sex])[0]\n",
            "NameError: name 'sex_encoder' is not defined\n",
            "2024-07-02 17:54:52.738 Uncaught app exception\n",
            "Traceback (most recent call last):\n",
            "  File \"/usr/local/lib/python3.10/dist-packages/streamlit/runtime/scriptrunner/script_runner.py\", line 589, in _run_script\n",
            "    exec(code, module.__dict__)\n",
            "  File \"/content/web.py\", line 58, in <module>\n",
            "    main()\n",
            "  File \"/content/web.py\", line 33, in main\n",
            "    Sex=sex_encoder.fit_transform([Sex])[0]\n",
            "NameError: name 'sex_encoder' is not defined\n",
            "2024-07-02 17:55:54.066 Uncaught app exception\n",
            "Traceback (most recent call last):\n",
            "  File \"/usr/local/lib/python3.10/dist-packages/streamlit/runtime/scriptrunner/script_runner.py\", line 589, in _run_script\n",
            "    exec(code, module.__dict__)\n",
            "  File \"/content/web.py\", line 58, in <module>\n",
            "    main()\n",
            "  File \"/content/web.py\", line 33, in main\n",
            "    Sex=sex_encoder.fit_transform([Sex])[0]\n",
            "NameError: name 'sex_encoder' is not defined\n",
            "2024-07-02 17:55:56.898 Uncaught app exception\n",
            "Traceback (most recent call last):\n",
            "  File \"/usr/local/lib/python3.10/dist-packages/streamlit/runtime/scriptrunner/script_runner.py\", line 589, in _run_script\n",
            "    exec(code, module.__dict__)\n",
            "  File \"/content/web.py\", line 58, in <module>\n",
            "    main()\n",
            "  File \"/content/web.py\", line 33, in main\n",
            "    Sex=sex_encoder.fit_transform([Sex])[0]\n",
            "NameError: name 'sex_encoder' is not defined\n",
            "2024-07-02 17:55:58.029 Uncaught app exception\n",
            "Traceback (most recent call last):\n",
            "  File \"/usr/local/lib/python3.10/dist-packages/streamlit/runtime/scriptrunner/script_runner.py\", line 589, in _run_script\n",
            "    exec(code, module.__dict__)\n",
            "  File \"/content/web.py\", line 58, in <module>\n",
            "    main()\n",
            "  File \"/content/web.py\", line 33, in main\n",
            "    Sex=sex_encoder.fit_transform([Sex])[0]\n",
            "NameError: name 'sex_encoder' is not defined\n",
            "2024-07-02 17:55:59.174 Uncaught app exception\n",
            "Traceback (most recent call last):\n",
            "  File \"/usr/local/lib/python3.10/dist-packages/streamlit/runtime/scriptrunner/script_runner.py\", line 589, in _run_script\n",
            "    exec(code, module.__dict__)\n",
            "  File \"/content/web.py\", line 58, in <module>\n",
            "    main()\n",
            "  File \"/content/web.py\", line 33, in main\n",
            "    Sex=sex_encoder.fit_transform([Sex])[0]\n",
            "NameError: name 'sex_encoder' is not defined\n",
            "2024-07-02 17:56:03.086 Uncaught app exception\n",
            "Traceback (most recent call last):\n",
            "  File \"/usr/local/lib/python3.10/dist-packages/streamlit/runtime/scriptrunner/script_runner.py\", line 589, in _run_script\n",
            "    exec(code, module.__dict__)\n",
            "  File \"/content/web.py\", line 58, in <module>\n",
            "    main()\n",
            "  File \"/content/web.py\", line 33, in main\n",
            "    Sex=sex_encoder.fit_transform([Sex])[0]\n",
            "NameError: name 'sex_encoder' is not defined\n",
            "2024-07-02 17:56:06.989 Uncaught app exception\n",
            "Traceback (most recent call last):\n",
            "  File \"/usr/local/lib/python3.10/dist-packages/streamlit/runtime/scriptrunner/script_runner.py\", line 589, in _run_script\n",
            "    exec(code, module.__dict__)\n",
            "  File \"/content/web.py\", line 58, in <module>\n",
            "    main()\n",
            "  File \"/content/web.py\", line 33, in main\n",
            "    Sex=sex_encoder.fit_transform([Sex])[0]\n",
            "NameError: name 'sex_encoder' is not defined\n",
            "2024-07-02 17:59:07.782 Uncaught app exception\n",
            "Traceback (most recent call last):\n",
            "  File \"/usr/local/lib/python3.10/dist-packages/streamlit/runtime/scriptrunner/script_runner.py\", line 589, in _run_script\n",
            "    exec(code, module.__dict__)\n",
            "  File \"/content/web.py\", line 59, in <module>\n",
            "    main()\n",
            "  File \"/content/web.py\", line 32, in main\n",
            "    sex_\n",
            "NameError: name 'sex_' is not defined\n",
            "2024-07-02 17:59:12.300 Uncaught app exception\n",
            "Traceback (most recent call last):\n",
            "  File \"/usr/local/lib/python3.10/dist-packages/streamlit/runtime/scriptrunner/script_runner.py\", line 589, in _run_script\n",
            "    exec(code, module.__dict__)\n",
            "  File \"/content/web.py\", line 59, in <module>\n",
            "    main()\n",
            "  File \"/content/web.py\", line 32, in main\n",
            "    sex_encoder\n",
            "NameError: name 'sex_encoder' is not defined\n",
            "2024-07-02 17:59:16.855 Uncaught app exception\n",
            "Traceback (most recent call last):\n",
            "  File \"/usr/local/lib/python3.10/dist-packages/streamlit/runtime/scriptrunner/script_runner.py\", line 589, in _run_script\n",
            "    exec(code, module.__dict__)\n",
            "  File \"/content/web.py\", line 59, in <module>\n",
            "    main()\n",
            "  File \"/content/web.py\", line 32, in main\n",
            "    sex_encoder=Label\n",
            "NameError: name 'Label' is not defined\n",
            "2024-07-02 17:59:24.268 Uncaught app exception\n",
            "Traceback (most recent call last):\n",
            "  File \"/usr/local/lib/python3.10/dist-packages/streamlit/runtime/scriptrunner/script_runner.py\", line 589, in _run_script\n",
            "    exec(code, module.__dict__)\n",
            "  File \"/content/web.py\", line 60, in <module>\n",
            "    main()\n",
            "  File \"/content/web.py\", line 38, in main\n",
            "    Embarked=embarked_encoder.fit_transform([Embarked])[0]\n",
            "NameError: name 'embarked_encoder' is not defined\n",
            "2024-07-02 17:59:43.186 Uncaught app exception\n",
            "Traceback (most recent call last):\n",
            "  File \"/usr/local/lib/python3.10/dist-packages/streamlit/runtime/scriptrunner/script_runner.py\", line 589, in _run_script\n",
            "    exec(code, module.__dict__)\n",
            "  File \"/content/web.py\", line 60, in <module>\n",
            "    main()\n",
            "  File \"/content/web.py\", line 33, in main\n",
            "    embarked_encoder\n",
            "NameError: name 'embarked_encoder' is not defined\n",
            "2024-07-02 17:59:47.319 Uncaught app exception\n",
            "Traceback (most recent call last):\n",
            "  File \"/usr/local/lib/python3.10/dist-packages/streamlit/runtime/scriptrunner/script_runner.py\", line 589, in _run_script\n",
            "    exec(code, module.__dict__)\n",
            "  File \"/content/web.py\", line 60, in <module>\n",
            "    main()\n",
            "  File \"/content/web.py\", line 33, in main\n",
            "    embarked_encoder\n",
            "NameError: name 'embarked_encoder' is not defined\n",
            "/usr/local/lib/python3.10/dist-packages/sklearn/base.py:439: UserWarning: X does not have valid feature names, but RandomForestClassifier was fitted with feature names\n",
            "  warnings.warn(\n",
            "[0]\n",
            "/usr/local/lib/python3.10/dist-packages/sklearn/base.py:439: UserWarning: X does not have valid feature names, but RandomForestClassifier was fitted with feature names\n",
            "  warnings.warn(\n",
            "[0]\n",
            "/usr/local/lib/python3.10/dist-packages/sklearn/base.py:439: UserWarning: X does not have valid feature names, but RandomForestClassifier was fitted with feature names\n",
            "  warnings.warn(\n",
            "[1]\n",
            "2024-07-02 18:31:13.233 Uncaught app exception\n",
            "Traceback (most recent call last):\n",
            "  File \"/usr/local/lib/python3.10/dist-packages/streamlit/runtime/scriptrunner/script_runner.py\", line 589, in _run_script\n",
            "    exec(code, module.__dict__)\n",
            "  File \"/content/web.py\", line 61, in <module>\n",
            "    main()\n",
            "  File \"/content/web.py\", line 42, in main\n",
            "    columns=(model1,mos)\n",
            "NameError: name 'mos' is not defined\n",
            "2024-07-02 18:37:06.264 Uncaught app exception\n",
            "Traceback (most recent call last):\n",
            "  File \"/usr/local/lib/python3.10/dist-packages/streamlit/runtime/scriptrunner/script_runner.py\", line 589, in _run_script\n",
            "    exec(code, module.__dict__)\n",
            "  File \"/content/web.py\", line 60, in <module>\n",
            "    main()\n",
            "  File \"/content/web.py\", line 43, in main\n",
            "    for models in st.multiselect('choose a plot',columns):\n",
            "NameError: name 'columns' is not defined\n",
            "2024-07-02 18:37:11.401 Uncaught app exception\n",
            "Traceback (most recent call last):\n",
            "  File \"/usr/local/lib/python3.10/dist-packages/streamlit/runtime/scriptrunner/script_runner.py\", line 589, in _run_script\n",
            "    exec(code, module.__dict__)\n",
            "  File \"/content/web.py\", line 60, in <module>\n",
            "    main()\n",
            "  File \"/content/web.py\", line 43, in main\n",
            "    for models in st.multiselect('choose a plot',columns):\n",
            "NameError: name 'columns' is not defined\n",
            "2024-07-02 18:37:19.229 Uncaught app exception\n",
            "Traceback (most recent call last):\n",
            "  File \"/usr/local/lib/python3.10/dist-packages/streamlit/runtime/scriptrunner/script_runner.py\", line 589, in _run_script\n",
            "    exec(code, module.__dict__)\n",
            "  File \"/content/web.py\", line 60, in <module>\n",
            "    main()\n",
            "  File \"/content/web.py\", line 43, in main\n",
            "    for models in st.multiselect('choose a plot',columns):\n",
            "NameError: name 'columns' is not defined\n",
            "2024-07-02 18:37:35.609 Uncaught app exception\n",
            "Traceback (most recent call last):\n",
            "  File \"/usr/local/lib/python3.10/dist-packages/streamlit/runtime/scriptrunner/script_runner.py\", line 589, in _run_script\n",
            "    exec(code, module.__dict__)\n",
            "  File \"/content/web.py\", line 60, in <module>\n",
            "    main()\n",
            "  File \"/content/web.py\", line 55, in main\n",
            "    survive=survival_prediction([Age,SibSp,Pclass,Parch,PassengerId,Sex,Fare,Embarked])\n",
            "  File \"/content/web.py\", line 18, in survival_prediction\n",
            "    prediction=model.predict(b)\n",
            "NameError: name 'model' is not defined\n",
            "2024-07-02 18:39:43.133 Uncaught app exception\n",
            "Traceback (most recent call last):\n",
            "  File \"/usr/local/lib/python3.10/dist-packages/streamlit/runtime/scriptrunner/script_runner.py\", line 589, in _run_script\n",
            "    exec(code, module.__dict__)\n",
            "  File \"/content/web.py\", line 56, in <module>\n",
            "    main()\n",
            "  File \"/content/web.py\", line 51, in main\n",
            "    survive=survival_prediction([Age,SibSp,Pclass,Parch,PassengerId,Sex,Fare,Embarked])\n",
            "  File \"/content/web.py\", line 28, in survival_prediction\n",
            "    if (prediction[0] == 0):\n",
            "UnboundLocalError: local variable 'prediction' referenced before assignment\n",
            "2024-07-02 18:40:30.849 Uncaught app exception\n",
            "Traceback (most recent call last):\n",
            "  File \"/usr/local/lib/python3.10/dist-packages/streamlit/runtime/scriptrunner/script_runner.py\", line 589, in _run_script\n",
            "    exec(code, module.__dict__)\n",
            "  File \"/content/web.py\", line 57, in <module>\n",
            "    main()\n",
            "  File \"/content/web.py\", line 52, in main\n",
            "    survive=survival_prediction([Age,SibSp,Pclass,Parch,PassengerId,Sex,Fare,Embarked])\n",
            "  File \"/content/web.py\", line 27, in survival_prediction\n",
            "    return prediction\n",
            "UnboundLocalError: local variable 'prediction' referenced before assignment\n",
            "2024-07-02 18:41:07.080 Uncaught app exception\n",
            "Traceback (most recent call last):\n",
            "  File \"/usr/local/lib/python3.10/dist-packages/streamlit/runtime/scriptrunner/script_runner.py\", line 589, in _run_script\n",
            "    exec(code, module.__dict__)\n",
            "  File \"/content/web.py\", line 56, in <module>\n",
            "    main()\n",
            "  File \"/content/web.py\", line 51, in main\n",
            "    survive=survival_prediction([Age,SibSp,Pclass,Parch,PassengerId,Sex,Fare,Embarked])\n",
            "  File \"/content/web.py\", line 28, in survival_prediction\n",
            "    if (prediction[0] == 0):\n",
            "UnboundLocalError: local variable 'prediction' referenced before assignment\n",
            "2024-07-02 18:47:50.950 Uncaught app exception\n",
            "Traceback (most recent call last):\n",
            "  File \"/usr/local/lib/python3.10/dist-packages/streamlit/runtime/scriptrunner/script_runner.py\", line 589, in _run_script\n",
            "    exec(code, module.__dict__)\n",
            "  File \"/content/web.py\", line 61, in <module>\n",
            "    main()\n",
            "  File \"/content/web.py\", line 56, in main\n",
            "    survive=survival_prediction([Age,SibSp,Pclass,Parch,PassengerId,Sex,Fare,Embarked])\n",
            "  File \"/content/web.py\", line 18, in survival_prediction\n",
            "    for models in st.selectbox('choose a model',model1,model2):\n",
            "  File \"/usr/local/lib/python3.10/dist-packages/streamlit/runtime/metrics_util.py\", line 408, in wrapped_func\n",
            "    result = non_optional_func(*args, **kwargs)\n",
            "  File \"/usr/local/lib/python3.10/dist-packages/streamlit/elements/widgets/selectbox.py\", line 206, in selectbox\n",
            "    return self._selectbox(\n",
            "  File \"/usr/local/lib/python3.10/dist-packages/streamlit/elements/widgets/selectbox.py\", line 264, in _selectbox\n",
            "    raise StreamlitAPIException(\n",
            "streamlit.errors.StreamlitAPIException: Selectbox Value has invalid type: KNeighborsClassifier\n",
            "2024-07-02 18:50:36.494 Uncaught app exception\n",
            "Traceback (most recent call last):\n",
            "  File \"/usr/local/lib/python3.10/dist-packages/streamlit/runtime/scriptrunner/script_runner.py\", line 589, in _run_script\n",
            "    exec(code, module.__dict__)\n",
            "  File \"/content/web.py\", line 59, in <module>\n",
            "    main()\n",
            "  File \"/content/web.py\", line 45, in main\n",
            "    if (prediction[0] == 0):\n",
            "NameError: name 'prediction' is not defined\n",
            "2024-07-02 18:51:22.193 Uncaught app exception\n",
            "Traceback (most recent call last):\n",
            "  File \"/usr/local/lib/python3.10/dist-packages/streamlit/runtime/scriptrunner/script_runner.py\", line 589, in _run_script\n",
            "    exec(code, module.__dict__)\n",
            "  File \"/content/web.py\", line 59, in <module>\n",
            "    main()\n",
            "  File \"/content/web.py\", line 54, in main\n",
            "    survive=survival_prediction([Age,SibSp,Pclass,Parch,PassengerId,Sex,Fare,Embarked])\n",
            "  File \"/content/web.py\", line 28, in survival_prediction\n",
            "    if (prediction[0] == 0):\n",
            "UnboundLocalError: local variable 'prediction' referenced before assignment\n",
            "2024-07-02 18:57:16.055 Uncaught app exception\n",
            "Traceback (most recent call last):\n",
            "  File \"/usr/local/lib/python3.10/dist-packages/streamlit/runtime/scriptrunner/script_runner.py\", line 589, in _run_script\n",
            "    exec(code, module.__dict__)\n",
            "  File \"/content/web.py\", line 59, in <module>\n",
            "    main()\n",
            "  File \"/content/web.py\", line 54, in main\n",
            "    survive=survival_prediction([Age,SibSp,Pclass,Parch,PassengerId,Sex,Fare,Embarked])\n",
            "  File \"/content/web.py\", line 28, in survival_prediction\n",
            "    if (prediction[0] == 0):\n",
            "UnboundLocalError: local variable 'prediction' referenced before assignment\n",
            "2024-07-02 19:03:04.002 Uncaught app exception\n",
            "Traceback (most recent call last):\n",
            "  File \"/usr/local/lib/python3.10/dist-packages/streamlit/runtime/scriptrunner/script_runner.py\", line 589, in _run_script\n",
            "    exec(code, module.__dict__)\n",
            "  File \"/content/web.py\", line 64, in <module>\n",
            "    main()\n",
            "  File \"/content/web.py\", line 59, in main\n",
            "    survive=survival_prediction([Age,SibSp,Pclass,Parch,PassengerId,Sex,Fare,Embarked])\n",
            "  File \"/content/web.py\", line 18, in survival_prediction\n",
            "    for model in models(model1,model2):\n",
            "TypeError: 'tuple' object is not callable\n",
            "2024-07-02 19:06:13.198 Uncaught app exception\n",
            "Traceback (most recent call last):\n",
            "  File \"/usr/local/lib/python3.10/dist-packages/streamlit/runtime/scriptrunner/script_runner.py\", line 589, in _run_script\n",
            "    exec(code, module.__dict__)\n",
            "  File \"/content/web.py\", line 43, in <module>\n",
            "    main()\n",
            "NameError: name 'main' is not defined\n",
            "2024-07-02 19:09:51.640 Uncaught app exception\n",
            "Traceback (most recent call last):\n",
            "  File \"/usr/local/lib/python3.10/dist-packages/streamlit/runtime/scriptrunner/script_runner.py\", line 589, in _run_script\n",
            "    exec(code, module.__dict__)\n",
            "  File \"/content/web.py\", line 61, in <module>\n",
            "    main()\n",
            "  File \"/content/web.py\", line 27, in main\n",
            "    models=st.selectbox(['model1','model2'])\n",
            "  File \"/usr/local/lib/python3.10/dist-packages/streamlit/runtime/metrics_util.py\", line 408, in wrapped_func\n",
            "    result = non_optional_func(*args, **kwargs)\n",
            "TypeError: SelectboxMixin.selectbox() missing 1 required positional argument: 'options'\n",
            "2024-07-02 19:09:55.960 Uncaught app exception\n",
            "Traceback (most recent call last):\n",
            "  File \"/usr/local/lib/python3.10/dist-packages/streamlit/runtime/scriptrunner/script_runner.py\", line 589, in _run_script\n",
            "    exec(code, module.__dict__)\n",
            "  File \"/content/web.py\", line 61, in <module>\n",
            "    main()\n",
            "  File \"/content/web.py\", line 27, in main\n",
            "    models=st.selectbox(['model1','model2'])\n",
            "  File \"/usr/local/lib/python3.10/dist-packages/streamlit/runtime/metrics_util.py\", line 408, in wrapped_func\n",
            "    result = non_optional_func(*args, **kwargs)\n",
            "TypeError: SelectboxMixin.selectbox() missing 1 required positional argument: 'options'\n",
            "2024-07-02 19:10:14.279 Uncaught app exception\n",
            "Traceback (most recent call last):\n",
            "  File \"/usr/local/lib/python3.10/dist-packages/streamlit/runtime/scriptrunner/script_runner.py\", line 589, in _run_script\n",
            "    exec(code, module.__dict__)\n",
            "  File \"/content/web.py\", line 61, in <module>\n",
            "    main()\n",
            "  File \"/content/web.py\", line 27, in main\n",
            "    models=st.selectbox(['model1','model2'])\n",
            "  File \"/usr/local/lib/python3.10/dist-packages/streamlit/runtime/metrics_util.py\", line 408, in wrapped_func\n",
            "    result = non_optional_func(*args, **kwargs)\n",
            "TypeError: SelectboxMixin.selectbox() missing 1 required positional argument: 'options'\n",
            "2024-07-02 19:12:06.743 Uncaught app exception\n",
            "Traceback (most recent call last):\n",
            "  File \"/usr/local/lib/python3.10/dist-packages/streamlit/runtime/scriptrunner/script_runner.py\", line 589, in _run_script\n",
            "    exec(code, module.__dict__)\n",
            "  File \"/content/web.py\", line 61, in <module>\n",
            "    main()\n",
            "  File \"/content/web.py\", line 56, in main\n",
            "    survive=survival_prediction([Age,SibSp,Pclass,Parch,PassengerId,Sex,Fare,Embarked])\n",
            "  File \"/content/web.py\", line 18, in survival_prediction\n",
            "    for model in models(model1,model2):\n",
            "TypeError: 'tuple' object is not callable\n",
            "2024-07-02 19:12:44.122 Uncaught app exception\n",
            "Traceback (most recent call last):\n",
            "  File \"/usr/local/lib/python3.10/dist-packages/streamlit/runtime/scriptrunner/script_runner.py\", line 589, in _run_script\n",
            "    exec(code, module.__dict__)\n",
            "  File \"/content/web.py\", line 58, in <module>\n",
            "    st.success(survive)\n",
            "NameError: name 'survive' is not defined\n",
            "2024-07-02 19:14:14.128 Uncaught app exception\n",
            "Traceback (most recent call last):\n",
            "  File \"/usr/local/lib/python3.10/dist-packages/streamlit/runtime/scriptrunner/script_runner.py\", line 589, in _run_script\n",
            "    exec(code, module.__dict__)\n",
            "  File \"/content/web.py\", line 32, in <module>\n",
            "    st.success(survive)\n",
            "NameError: name 'survive' is not defined\n",
            "2024-07-02 19:15:06.047 Uncaught app exception\n",
            "Traceback (most recent call last):\n",
            "  File \"/usr/local/lib/python3.10/dist-packages/streamlit/runtime/scriptrunner/script_runner.py\", line 589, in _run_script\n",
            "    exec(code, module.__dict__)\n",
            "  File \"/content/web.py\", line 61, in <module>\n",
            "    main()\n",
            "  File \"/content/web.py\", line 30, in main\n",
            "    survive=survival_prediction([Age,SibSp,Pclass,Parch,PassengerId,Sex,Fare,Embarked])\n",
            "  File \"/content/web.py\", line 39, in survival_prediction\n",
            "    for model in models(model1,model2):\n",
            "NameError: name 'models' is not defined\n",
            "2024-07-02 19:15:51.747 Uncaught app exception\n",
            "Traceback (most recent call last):\n",
            "  File \"/usr/local/lib/python3.10/dist-packages/streamlit/runtime/scriptrunner/script_runner.py\", line 589, in _run_script\n",
            "    exec(code, module.__dict__)\n",
            "  File \"/content/web.py\", line 61, in <module>\n",
            "    main()\n",
            "  File \"/content/web.py\", line 30, in main\n",
            "    survive=survival_prediction([Age,SibSp,Pclass,Parch,PassengerId,Sex,Fare,Embarked])\n",
            "  File \"/content/web.py\", line 39, in survival_prediction\n",
            "    for model in models(model1,model2):\n",
            "TypeError: 'tuple' object is not callable\n",
            "2024-07-02 19:16:49.928 Uncaught app exception\n",
            "Traceback (most recent call last):\n",
            "  File \"/usr/local/lib/python3.10/dist-packages/streamlit/runtime/scriptrunner/script_runner.py\", line 589, in _run_script\n",
            "    exec(code, module.__dict__)\n",
            "  File \"/content/web.py\", line 61, in <module>\n",
            "    main()\n",
            "  File \"/content/web.py\", line 30, in main\n",
            "    survive=survival_prediction([Age,SibSp,Pclass,Parch,PassengerId,Sex,Fare,Embarked])\n",
            "  File \"/content/web.py\", line 39, in survival_prediction\n",
            "    for model in models(model1,model2):\n",
            "TypeError: 'tuple' object is not callable\n",
            "2024-07-02 19:19:43.214 Uncaught app exception\n",
            "Traceback (most recent call last):\n",
            "  File \"/usr/local/lib/python3.10/dist-packages/streamlit/runtime/scriptrunner/script_runner.py\", line 589, in _run_script\n",
            "    exec(code, module.__dict__)\n",
            "  File \"/content/web.py\", line 62, in <module>\n",
            "    main()\n",
            "  File \"/content/web.py\", line 30, in main\n",
            "    b=a.reshape(1,-1)\n",
            "AttributeError: 'LabelEncoder' object has no attribute 'reshape'\n",
            "2024-07-02 19:25:43.228 Uncaught app exception\n",
            "Traceback (most recent call last):\n",
            "  File \"/usr/local/lib/python3.10/dist-packages/streamlit/runtime/scriptrunner/script_runner.py\", line 589, in _run_script\n",
            "    exec(code, module.__dict__)\n",
            "  File \"/content/web.py\", line 58, in <module>\n",
            "    main()\n",
            "  File \"/content/web.py\", line 28, in main\n",
            "    a=np.asarray(input_data)\n",
            "NameError: name 'input_data' is not defined\n",
            "/usr/local/lib/python3.10/dist-packages/sklearn/base.py:439: UserWarning: X does not have valid feature names, but RandomForestClassifier was fitted with feature names\n",
            "  warnings.warn(\n",
            "[0]\n",
            "/usr/local/lib/python3.10/dist-packages/sklearn/base.py:439: UserWarning: X does not have valid feature names, but RandomForestClassifier was fitted with feature names\n",
            "  warnings.warn(\n",
            "[0]\n",
            "/usr/local/lib/python3.10/dist-packages/sklearn/base.py:439: UserWarning: X does not have valid feature names, but RandomForestClassifier was fitted with feature names\n",
            "  warnings.warn(\n",
            "[0]\n",
            "/usr/local/lib/python3.10/dist-packages/sklearn/base.py:439: UserWarning: X does not have valid feature names, but RandomForestClassifier was fitted with feature names\n",
            "  warnings.warn(\n",
            "[0]\n",
            "/usr/local/lib/python3.10/dist-packages/sklearn/base.py:439: UserWarning: X does not have valid feature names, but RandomForestClassifier was fitted with feature names\n",
            "  warnings.warn(\n",
            "[0]\n",
            "/usr/local/lib/python3.10/dist-packages/sklearn/base.py:439: UserWarning: X does not have valid feature names, but RandomForestClassifier was fitted with feature names\n",
            "  warnings.warn(\n",
            "[0]\n",
            "/usr/local/lib/python3.10/dist-packages/sklearn/base.py:439: UserWarning: X does not have valid feature names, but RandomForestClassifier was fitted with feature names\n",
            "  warnings.warn(\n",
            "[0]\n",
            "/usr/local/lib/python3.10/dist-packages/sklearn/base.py:439: UserWarning: X does not have valid feature names, but RandomForestClassifier was fitted with feature names\n",
            "  warnings.warn(\n",
            "[0]\n",
            "/usr/local/lib/python3.10/dist-packages/sklearn/base.py:439: UserWarning: X does not have valid feature names, but RandomForestClassifier was fitted with feature names\n",
            "  warnings.warn(\n",
            "[0]\n",
            "2024-07-02 19:46:43.238 Uncaught app exception\n",
            "Traceback (most recent call last):\n",
            "  File \"/usr/local/lib/python3.10/dist-packages/streamlit/runtime/scriptrunner/script_runner.py\", line 589, in _run_script\n",
            "    exec(code, module.__dict__)\n",
            "  File \"/content/web.py\", line 62, in <module>\n",
            "    main()\n",
            "  File \"/content/web.py\", line 32, in main\n",
            "    Parch=st.number_input('Pclass',0,5)\n",
            "  File \"/usr/local/lib/python3.10/dist-packages/streamlit/runtime/metrics_util.py\", line 408, in wrapped_func\n",
            "    result = non_optional_func(*args, **kwargs)\n",
            "  File \"/usr/local/lib/python3.10/dist-packages/streamlit/elements/widgets/number_input.py\", line 248, in number_input\n",
            "    return self._number_input(\n",
            "  File \"/usr/local/lib/python3.10/dist-packages/streamlit/elements/widgets/number_input.py\", line 457, in _number_input\n",
            "    widget_state = register_widget(\n",
            "  File \"/usr/local/lib/python3.10/dist-packages/streamlit/runtime/state/widgets.py\", line 167, in register_widget\n",
            "    return register_widget_from_metadata(metadata, ctx, widget_func_name, element_type)\n",
            "  File \"/usr/local/lib/python3.10/dist-packages/streamlit/runtime/state/widgets.py\", line 212, in register_widget_from_metadata\n",
            "    raise DuplicateWidgetID(\n",
            "streamlit.errors.DuplicateWidgetID: There are multiple identical `st.number_input` widgets with the\n",
            "same generated key.\n",
            "\n",
            "When a widget is created, it's assigned an internal key based on\n",
            "its structure. Multiple widgets with an identical structure will\n",
            "result in the same internal key, which causes this error.\n",
            "\n",
            "To fix this error, please pass a unique `key` argument to\n",
            "`st.number_input`.\n",
            "/usr/local/lib/python3.10/dist-packages/sklearn/base.py:439: UserWarning: X does not have valid feature names, but RandomForestClassifier was fitted with feature names\n",
            "  warnings.warn(\n",
            "[0]\n",
            "2024-07-02 19:50:31.292 Uncaught app exception\n",
            "Traceback (most recent call last):\n",
            "  File \"/usr/local/lib/python3.10/dist-packages/streamlit/runtime/scriptrunner/script_runner.py\", line 589, in _run_script\n",
            "    exec(code, module.__dict__)\n",
            "  File \"/content/web.py\", line 62, in <module>\n",
            "    main()\n",
            "  File \"/content/web.py\", line 43, in main\n",
            "    for columns in st.sidebar.multiselect(columns):\n",
            "  File \"/usr/local/lib/python3.10/dist-packages/streamlit/runtime/metrics_util.py\", line 408, in wrapped_func\n",
            "    result = non_optional_func(*args, **kwargs)\n",
            "TypeError: MultiSelectMixin.multiselect() missing 1 required positional argument: 'options'\n",
            "2024-07-02 19:50:39.396 Uncaught app exception\n",
            "Traceback (most recent call last):\n",
            "  File \"/usr/local/lib/python3.10/dist-packages/streamlit/runtime/scriptrunner/script_runner.py\", line 589, in _run_script\n",
            "    exec(code, module.__dict__)\n",
            "  File \"/content/web.py\", line 62, in <module>\n",
            "    main()\n",
            "  File \"/content/web.py\", line 43, in main\n",
            "    for columns in st.sidebar.multiselect(columns):\n",
            "  File \"/usr/local/lib/python3.10/dist-packages/streamlit/runtime/metrics_util.py\", line 408, in wrapped_func\n",
            "    result = non_optional_func(*args, **kwargs)\n",
            "TypeError: MultiSelectMixin.multiselect() missing 1 required positional argument: 'options'\n",
            "2024-07-02 19:51:10.579 `label` got an empty value. This is discouraged for accessibility reasons and may be disallowed in the future by raising an exception. Please provide a non-empty label and hide it with label_visibility if needed.\n",
            "2024-07-02 19:51:43.335 `label` got an empty value. This is discouraged for accessibility reasons and may be disallowed in the future by raising an exception. Please provide a non-empty label and hide it with label_visibility if needed.\n",
            "2024-07-02 19:51:48.744 `label` got an empty value. This is discouraged for accessibility reasons and may be disallowed in the future by raising an exception. Please provide a non-empty label and hide it with label_visibility if needed.\n",
            "2024-07-02 19:52:19.556 `label` got an empty value. This is discouraged for accessibility reasons and may be disallowed in the future by raising an exception. Please provide a non-empty label and hide it with label_visibility if needed.\n",
            "2024-07-02 19:53:02.058 `label` got an empty value. This is discouraged for accessibility reasons and may be disallowed in the future by raising an exception. Please provide a non-empty label and hide it with label_visibility if needed.\n",
            "2024-07-02 19:53:08.468 `label` got an empty value. This is discouraged for accessibility reasons and may be disallowed in the future by raising an exception. Please provide a non-empty label and hide it with label_visibility if needed.\n",
            "2024-07-02 19:53:16.375 `label` got an empty value. This is discouraged for accessibility reasons and may be disallowed in the future by raising an exception. Please provide a non-empty label and hide it with label_visibility if needed.\n",
            "/usr/local/lib/python3.10/dist-packages/sklearn/base.py:439: UserWarning: X does not have valid feature names, but RandomForestClassifier was fitted with feature names\n",
            "  warnings.warn(\n",
            "2024-07-02 19:53:16.376 Uncaught app exception\n",
            "Traceback (most recent call last):\n",
            "  File \"/usr/local/lib/python3.10/dist-packages/streamlit/runtime/scriptrunner/script_runner.py\", line 589, in _run_script\n",
            "    exec(code, module.__dict__)\n",
            "  File \"/content/web.py\", line 63, in <module>\n",
            "    main()\n",
            "  File \"/content/web.py\", line 57, in main\n",
            "    survive=survival_prediction([Age,SibSp,Pclass,Parch,PassengerId,Sex,Fare,Embarked])\n",
            "  File \"/content/web.py\", line 19, in survival_prediction\n",
            "    prediction=model.predict(b)\n",
            "  File \"/usr/local/lib/python3.10/dist-packages/sklearn/ensemble/_forest.py\", line 820, in predict\n",
            "    proba = self.predict_proba(X)\n",
            "  File \"/usr/local/lib/python3.10/dist-packages/sklearn/ensemble/_forest.py\", line 862, in predict_proba\n",
            "    X = self._validate_X_predict(X)\n",
            "  File \"/usr/local/lib/python3.10/dist-packages/sklearn/ensemble/_forest.py\", line 602, in _validate_X_predict\n",
            "    X = self._validate_data(X, dtype=DTYPE, accept_sparse=\"csr\", reset=False)\n",
            "  File \"/usr/local/lib/python3.10/dist-packages/sklearn/base.py\", line 565, in _validate_data\n",
            "    X = check_array(X, input_name=\"X\", **check_params)\n",
            "  File \"/usr/local/lib/python3.10/dist-packages/sklearn/utils/validation.py\", line 879, in check_array\n",
            "    array = _asarray_with_order(array, order=order, dtype=dtype, xp=xp)\n",
            "  File \"/usr/local/lib/python3.10/dist-packages/sklearn/utils/_array_api.py\", line 185, in _asarray_with_order\n",
            "    array = numpy.asarray(array, order=order, dtype=dtype)\n",
            "ValueError: could not convert string to float: ''\n",
            "2024-07-02 19:53:21.768 `label` got an empty value. This is discouraged for accessibility reasons and may be disallowed in the future by raising an exception. Please provide a non-empty label and hide it with label_visibility if needed.\n",
            "/usr/local/lib/python3.10/dist-packages/sklearn/base.py:439: UserWarning: X does not have valid feature names, but RandomForestClassifier was fitted with feature names\n",
            "  warnings.warn(\n",
            "2024-07-02 19:53:21.769 Uncaught app exception\n",
            "Traceback (most recent call last):\n",
            "  File \"/usr/local/lib/python3.10/dist-packages/streamlit/runtime/scriptrunner/script_runner.py\", line 589, in _run_script\n",
            "    exec(code, module.__dict__)\n",
            "  File \"/content/web.py\", line 63, in <module>\n",
            "    main()\n",
            "  File \"/content/web.py\", line 57, in main\n",
            "    survive=survival_prediction([Age,SibSp,Pclass,Parch,PassengerId,Sex,Fare,Embarked])\n",
            "  File \"/content/web.py\", line 19, in survival_prediction\n",
            "    prediction=model.predict(b)\n",
            "  File \"/usr/local/lib/python3.10/dist-packages/sklearn/ensemble/_forest.py\", line 820, in predict\n",
            "    proba = self.predict_proba(X)\n",
            "  File \"/usr/local/lib/python3.10/dist-packages/sklearn/ensemble/_forest.py\", line 862, in predict_proba\n",
            "    X = self._validate_X_predict(X)\n",
            "  File \"/usr/local/lib/python3.10/dist-packages/sklearn/ensemble/_forest.py\", line 602, in _validate_X_predict\n",
            "    X = self._validate_data(X, dtype=DTYPE, accept_sparse=\"csr\", reset=False)\n",
            "  File \"/usr/local/lib/python3.10/dist-packages/sklearn/base.py\", line 565, in _validate_data\n",
            "    X = check_array(X, input_name=\"X\", **check_params)\n",
            "  File \"/usr/local/lib/python3.10/dist-packages/sklearn/utils/validation.py\", line 879, in check_array\n",
            "    array = _asarray_with_order(array, order=order, dtype=dtype, xp=xp)\n",
            "  File \"/usr/local/lib/python3.10/dist-packages/sklearn/utils/_array_api.py\", line 185, in _asarray_with_order\n",
            "    array = numpy.asarray(array, order=order, dtype=dtype)\n",
            "ValueError: could not convert string to float: ''\n",
            "2024-07-02 19:53:22.656 `label` got an empty value. This is discouraged for accessibility reasons and may be disallowed in the future by raising an exception. Please provide a non-empty label and hide it with label_visibility if needed.\n",
            "/usr/local/lib/python3.10/dist-packages/sklearn/base.py:439: UserWarning: X does not have valid feature names, but RandomForestClassifier was fitted with feature names\n",
            "  warnings.warn(\n",
            "2024-07-02 19:53:22.657 Uncaught app exception\n",
            "Traceback (most recent call last):\n",
            "  File \"/usr/local/lib/python3.10/dist-packages/streamlit/runtime/scriptrunner/script_runner.py\", line 589, in _run_script\n",
            "    exec(code, module.__dict__)\n",
            "  File \"/content/web.py\", line 63, in <module>\n",
            "    main()\n",
            "  File \"/content/web.py\", line 57, in main\n",
            "    survive=survival_prediction([Age,SibSp,Pclass,Parch,PassengerId,Sex,Fare,Embarked])\n",
            "  File \"/content/web.py\", line 19, in survival_prediction\n",
            "    prediction=model.predict(b)\n",
            "  File \"/usr/local/lib/python3.10/dist-packages/sklearn/ensemble/_forest.py\", line 820, in predict\n",
            "    proba = self.predict_proba(X)\n",
            "  File \"/usr/local/lib/python3.10/dist-packages/sklearn/ensemble/_forest.py\", line 862, in predict_proba\n",
            "    X = self._validate_X_predict(X)\n",
            "  File \"/usr/local/lib/python3.10/dist-packages/sklearn/ensemble/_forest.py\", line 602, in _validate_X_predict\n",
            "    X = self._validate_data(X, dtype=DTYPE, accept_sparse=\"csr\", reset=False)\n",
            "  File \"/usr/local/lib/python3.10/dist-packages/sklearn/base.py\", line 565, in _validate_data\n",
            "    X = check_array(X, input_name=\"X\", **check_params)\n",
            "  File \"/usr/local/lib/python3.10/dist-packages/sklearn/utils/validation.py\", line 879, in check_array\n",
            "    array = _asarray_with_order(array, order=order, dtype=dtype, xp=xp)\n",
            "  File \"/usr/local/lib/python3.10/dist-packages/sklearn/utils/_array_api.py\", line 185, in _asarray_with_order\n",
            "    array = numpy.asarray(array, order=order, dtype=dtype)\n",
            "ValueError: could not convert string to float: ''\n",
            "2024-07-02 19:54:10.711 Uncaught app exception\n",
            "Traceback (most recent call last):\n",
            "  File \"/usr/local/lib/python3.10/dist-packages/streamlit/runtime/scriptrunner/script_runner.py\", line 589, in _run_script\n",
            "    exec(code, module.__dict__)\n",
            "  File \"/content/web.py\", line 60, in <module>\n",
            "    st.success(survive)\n",
            "NameError: name 'survive' is not defined\n",
            "2024-07-02 19:54:21.425 `label` got an empty value. This is discouraged for accessibility reasons and may be disallowed in the future by raising an exception. Please provide a non-empty label and hide it with label_visibility if needed.\n",
            "2024-07-02 19:54:27.704 `label` got an empty value. This is discouraged for accessibility reasons and may be disallowed in the future by raising an exception. Please provide a non-empty label and hide it with label_visibility if needed.\n",
            "2024-07-02 19:54:34.220 `label` got an empty value. This is discouraged for accessibility reasons and may be disallowed in the future by raising an exception. Please provide a non-empty label and hide it with label_visibility if needed.\n",
            "2024-07-02 19:54:40.097 `label` got an empty value. This is discouraged for accessibility reasons and may be disallowed in the future by raising an exception. Please provide a non-empty label and hide it with label_visibility if needed.\n",
            "2024-07-02 19:54:46.593 `label` got an empty value. This is discouraged for accessibility reasons and may be disallowed in the future by raising an exception. Please provide a non-empty label and hide it with label_visibility if needed.\n",
            "/usr/local/lib/python3.10/dist-packages/sklearn/base.py:439: UserWarning: X does not have valid feature names, but RandomForestClassifier was fitted with feature names\n",
            "  warnings.warn(\n",
            "2024-07-02 19:55:59.997 Uncaught app exception\n",
            "Traceback (most recent call last):\n",
            "  File \"/usr/local/lib/python3.10/dist-packages/streamlit/runtime/scriptrunner/script_runner.py\", line 589, in _run_script\n",
            "    exec(code, module.__dict__)\n",
            "  File \"/content/web.py\", line 60, in <module>\n",
            "    main()\n",
            "  File \"/content/web.py\", line 55, in main\n",
            "    survive=survival_prediction([Age,SibSp,Pclass,Parch,PassengerId,Sex,Fare,Embarked])\n",
            "  File \"/content/web.py\", line 17, in survival_prediction\n",
            "    prediction=model.predict(b)\n",
            "  File \"/usr/local/lib/python3.10/dist-packages/sklearn/ensemble/_forest.py\", line 820, in predict\n",
            "    proba = self.predict_proba(X)\n",
            "  File \"/usr/local/lib/python3.10/dist-packages/sklearn/ensemble/_forest.py\", line 862, in predict_proba\n",
            "    X = self._validate_X_predict(X)\n",
            "  File \"/usr/local/lib/python3.10/dist-packages/sklearn/ensemble/_forest.py\", line 602, in _validate_X_predict\n",
            "    X = self._validate_data(X, dtype=DTYPE, accept_sparse=\"csr\", reset=False)\n",
            "  File \"/usr/local/lib/python3.10/dist-packages/sklearn/base.py\", line 565, in _validate_data\n",
            "    X = check_array(X, input_name=\"X\", **check_params)\n",
            "  File \"/usr/local/lib/python3.10/dist-packages/sklearn/utils/validation.py\", line 879, in check_array\n",
            "    array = _asarray_with_order(array, order=order, dtype=dtype, xp=xp)\n",
            "  File \"/usr/local/lib/python3.10/dist-packages/sklearn/utils/_array_api.py\", line 185, in _asarray_with_order\n",
            "    array = numpy.asarray(array, order=order, dtype=dtype)\n",
            "ValueError: could not convert string to float: ''\n",
            "2024-07-02 19:58:55.180 Uncaught app exception\n",
            "Traceback (most recent call last):\n",
            "  File \"/usr/local/lib/python3.10/dist-packages/streamlit/runtime/scriptrunner/script_runner.py\", line 589, in _run_script\n",
            "    exec(code, module.__dict__)\n",
            "  File \"/content/web.py\", line 59, in <module>\n",
            "    main()\n",
            "  File \"/content/web.py\", line 41, in main\n",
            "    Parch=st.num_input('Parch',0,5)\n",
            "AttributeError: module 'streamlit' has no attribute 'num_input'\n",
            "2024-07-02 20:01:06.197 Uncaught app exception\n",
            "Traceback (most recent call last):\n",
            "  File \"/usr/local/lib/python3.10/dist-packages/streamlit/runtime/scriptrunner/script_runner.py\", line 589, in _run_script\n",
            "    exec(code, module.__dict__)\n",
            "  File \"/content/web.py\", line 59, in <module>\n",
            "    main()\n",
            "  File \"/content/web.py\", line 54, in main\n",
            "    survive=survival_prediction([Age,SibSp,Pclass,Parch,PassengerId,Sex,Fare,Embarked])\n",
            "  File \"/content/web.py\", line 28, in survival_prediction\n",
            "    if (prediction[0] == 0):\n",
            "UnboundLocalError: local variable 'prediction' referenced before assignment\n",
            "2024-07-02 20:02:43.267 Uncaught app exception\n",
            "Traceback (most recent call last):\n",
            "  File \"/usr/local/lib/python3.10/dist-packages/streamlit/runtime/scriptrunner/script_runner.py\", line 589, in _run_script\n",
            "    exec(code, module.__dict__)\n",
            "  File \"/content/web.py\", line 60, in <module>\n",
            "    main()\n",
            "  File \"/content/web.py\", line 29, in main\n",
            "    Pclass=st.b('Pclass',0,5)\n",
            "AttributeError: module 'streamlit' has no attribute 'b'\n",
            "/usr/local/lib/python3.10/dist-packages/sklearn/base.py:439: UserWarning: X does not have valid feature names, but RandomForestClassifier was fitted with feature names\n",
            "  warnings.warn(\n",
            "[0]\n",
            "2024-07-02 20:05:27.805 Uncaught app exception\n",
            "Traceback (most recent call last):\n",
            "  File \"/usr/local/lib/python3.10/dist-packages/streamlit/runtime/scriptrunner/script_runner.py\", line 589, in _run_script\n",
            "    exec(code, module.__dict__)\n",
            "  File \"/content/web.py\", line 61, in <module>\n",
            "    main()\n",
            "  File \"/content/web.py\", line 57, in main\n",
            "    time.sleep(3)\n",
            "NameError: name 'time' is not defined\n",
            "2024-07-02 20:06:43.201 Uncaught app exception\n",
            "Traceback (most recent call last):\n",
            "  File \"/usr/local/lib/python3.10/dist-packages/streamlit/runtime/scriptrunner/script_runner.py\", line 589, in _run_script\n",
            "    exec(code, module.__dict__)\n",
            "  File \"/content/web.py\", line 61, in <module>\n",
            "    main()\n",
            "  File \"/content/web.py\", line 57, in main\n",
            "    time.sleep(3)\n",
            "NameError: name 'time' is not defined\n",
            "/usr/local/lib/python3.10/dist-packages/sklearn/base.py:439: UserWarning: X does not have valid feature names, but RandomForestClassifier was fitted with feature names\n",
            "  warnings.warn(\n",
            "[0]\n",
            "\u001b[34m  Stopping...\u001b[0m\n",
            "^C\n"
          ]
        }
      ],
      "source": [
        "!streamlit run web.py & npx localtunnel --port 8501"
      ]
    }
  ],
  "metadata": {
    "colab": {
      "provenance": []
    },
    "kernelspec": {
      "display_name": "Python 3",
      "name": "python3"
    },
    "language_info": {
      "name": "python"
    }
  },
  "nbformat": 4,
  "nbformat_minor": 0
}